Workbook

Sheet Model_1
A1: Limit to growth | G1: Entry flow, car/ hour | H1: Number of cars_1, car | I1: Exit flow, car/ hour | J1: Number of passengers_1, people | K1: Rides per hour, ride/ hour | L1: Price per ride, $ | M1: Hourly incom per car_1, $/ hour | N1: Job attractiveness
A2: TIME STEP | B2: 1 | C2: hour | E2: 0 | F2: =E2*$B$2 -> 0 | G2: =MAX(0,J2*$B$4*$B$2*(N2-1)) -> 0 | H2: =B3 -> 300 | I2: 0 | J2: =B6 -> 1000 | K2: 0 | L2: 0 | M2: =K2*L2 -> 0 | N2: =M2/$B$10 -> 0
A3: Initial number of cars | B3: 300 | C3: car | E3: 1 | F3: =E3*$B$2 -> 1 | G3: =MAX(0,IF(N3>=1,J3*$B$4*$B$2*(N3-1),0)) -> 20 | H3: =H2+(G2-I2) -> 300 | I3: =H3*$B$5*$B$2*MAX(0,1-N3) -> 0 | J3: =IF(MOD(F3,3)=0,$B$6+$B$6*$B$12,IF(MOD(F3,7)=0,$B$6-$B$6*$B$12,$B$6)) -> 1000 | K3: =MIN($B$11,J3/H3) -> 3 | L3: =$B$8*(J3/(H3*K3)) -> 55.555556 | M3: =K3*L3 -> 166.66667 | N3: =M3/$B$10 -> 1.6666667
A4: Entry rate | B4: 0.03 | C4: car/ hour | E4: 2 | F4: =E4*$B$2 -> 2 | G4: =MAX(0,IF(N4>=1,J4*$B$4*$B$2*(N4-1),0)) -> 16.875 | H4: =H3+(G3-I3) -> 320 | I4: =H4*$B$5*$B$2*MAX(0,1-N4) -> 0 | J4: =IF(MOD(F4,3)=0,$B$6+$B$6*$B$12,IF(MOD(F4,7)=0,$B$6-$B$6*$B$12,$B$6)) -> 1000 | K4: =MIN($B$11,J4/H4) -> 3 | L4: =$B$8*(J4/(H4*K4)) -> 52.083333 | M4: =K4*L4 -> 156.25 | N4: =M4/$B$10 -> 1.5625
A5: Exit rate | B5: 0.04 | C5: car/ hour | E5: 3 | F5: =E5*$B$2 -> 3 | G5: =MAX(0,IF(N5>=1,J5*$B$4*$B$2*(N5-1),0)) -> 14.526902 | H5: =H4+(G4-I4) -> 336.875 | I5: =H5*$B$5*$B$2*MAX(0,1-N5) -> 0 | J5: =IF(MOD(F5,3)=0,$B$6+$B$6*$B$12,IF(MOD(F5,7)=0,$B$6-$B$6*$B$12,$B$6)) -> 1000 | K5: =MIN($B$11,J5/H5) -> 2.9684601 | L5: =$B$8*(J5/(H5*K5)) -> 50 | M5: =K5*L5 -> 148.42301 | N5: =M5/$B$10 -> 1.4842301
A6: Initial number of passengers | B6: 1000 | C6: people | E6: 4 | F6: =E6*$B$2 -> 4 | G6: =MAX(0,IF(N6>=1,J6*$B$4*$B$2*(N6-1),0)) -> 12.686166 | H6: =H5+(G5-I5) -> 351.4019 | I6: =H6*$B$5*$B$2*MAX(0,1-N6) -> 0 | J6: =IF(MOD(F6,3)=0,$B$6+$B$6*$B$12,IF(MOD(F6,7)=0,$B$6-$B$6*$B$12,$B$6)) -> 1000 | K6: =MIN($B$11,J6/H6) -> 2.8457444 | L6: =$B$8*(J6/(H6*K6)) -> 50 | M6: =K6*L6 -> 142.28722 | N6: =M6/$B$10 -> 1.4228722
A7: Average taxi ride time | B7: =20/60 -> 0.33333333 | C7: hour | E7: 5 | F7: =E7*$B$2 -> 5 | G7: =MAX(0,IF(N7>=1,J7*$B$4*$B$2*(N7-1),0)) -> 11.198823 | H7: =H6+(G6-I6) -> 364.08807 | I7: =H7*$B$5*$B$2*MAX(0,1-N7) -> 0 | J7: =IF(MOD(F7,3)=0,$B$6+$B$6*$B$12,IF(MOD(F7,7)=0,$B$6-$B$6*$B$12,$B$6)) -> 1000 | K7: =MIN($B$11,J7/H7) -> 2.7465882 | L7: =$B$8*(J7/(H7*K7)) -> 50 | M7: =K7*L7 -> 137.32941 | N7: =M7/$B$10 -> 1.3732941
A8: Price of 1 taxi ride | B8: 50 | C8: $ | E8: 6 | F8: =E8*$B$2 -> 6 | G8: =MAX(0,IF(N8>=1,J8*$B$4*$B$2*(N8-1),0)) -> 9.9694217 | H8: =H7+(G7-I7) -> 375.28689 | I8: =H8*$B$5*$B$2*MAX(0,1-N8) -> 0 | J8: =IF(MOD(F8,3)=0,$B$6+$B$6*$B$12,IF(MOD(F8,7)=0,$B$6-$B$6*$B$12,$B$6)) -> 1000 | K8: =MIN($B$11,J8/H8) -> 2.6646281 | L8: =$B$8*(J8/(H8*K8)) -> 50 | M8: =K8*L8 -> 133.23141 | N8: =M8/$B$10 -> 1.3323141
A9: Waiting time | B9: =5/60 -> 0.083333333 | C9: hour | E9: 7 | F9: =E9*$B$2 -> 7 | G9: =MAX(0,IF(N9>=1,J9*$B$4*$B$2*(N9-1),0)) -> 8.935118 | H9: =H8+(G8-I8) -> 385.25631 | I9: =H9*$B$5*$B$2*MAX(0,1-N9) -> 0 | J9: =IF(MOD(F9,3)=0,$B$6+$B$6*$B$12,IF(MOD(F9,7)=0,$B$6-$B$6*$B$12,$B$6)) -> 1000 | K9: =MIN($B$11,J9/H9) -> 2.5956745 | L9: =$B$8*(J9/(H9*K9)) -> 50 | M9: =K9*L9 -> 129.78373 | N9: =M9/$B$10 -> 1.2978373
A10: Target incom (2 rides for 50$ each) | B10: 100 | C10: $/hour | E10: 8 | F10: =E10*$B$2 -> 8 | G10: =MAX(0,IF(N10>=1,J10*$B$4*$B$2*(N10-1),0)) -> 8.0525776 | H10: =H9+(G9-I9) -> 394.19143 | I10: =H10*$B$5*$B$2*MAX(0,1-N10) -> 0 | J10: =IF(MOD(F10,3)=0,$B$6+$B$6*$B$12,IF(MOD(F10,7)=0,$B$6-$B$6*$B$12,$B$6)) -> 1000 | K10: =MIN($B$11,J10/H10) -> 2.5368385 | L10: =$B$8*(J10/(H10*K10)) -> 50 | M10: =K10*L10 -> 126.84193 | N10: =M10/$B$10 -> 1.2684193
A11: Max rides per hour | B11: =CEILING(1/(B7+B9),1) -> 3 | C11: ride/ hour | E11: 9 | F11: =E11*$B$2 -> 9 | G11: =MAX(0,IF(N11>=1,J11*$B$4*$B$2*(N11-1),0)) -> 7.2907978 | H11: =H10+(G10-I10) -> 402.24401 | I11: =H11*$B$5*$B$2*MAX(0,1-N11) -> 0 | J11: =IF(MOD(F11,3)=0,$B$6+$B$6*$B$12,IF(MOD(F11,7)=0,$B$6-$B$6*$B$12,$B$6)) -> 1000 | K11: =MIN($B$11,J11/H11) -> 2.4860532 | L11: =$B$8*(J11/(H11*K11)) -> 50 | M11: =K11*L11 -> 124.30266 | N11: =M11/$B$10 -> 1.2430266
A12: Demand variation | B12: 0 | E12: 10 | F12: =E12*$B$2 -> 10 | G12: =MAX(0,IF(N12>=1,J12*$B$4*$B$2*(N12-1),0)) -> 6.6269234 | H12: =H11+(G11-I11) -> 409.53481 | I12: =H12*$B$5*$B$2*MAX(0,1-N12) -> 0 | J12: =IF(MOD(F12,3)=0,$B$6+$B$6*$B$12,IF(MOD(F12,7)=0,$B$6-$B$6*$B$12,$B$6)) -> 1000 | K12: =MIN($B$11,J12/H12) -> 2.4417949 | L12: =$B$8*(J12/(H12*K12)) -> 50 | M12: =K12*L12 -> 122.08974 | N12: =M12/$B$10 -> 1.2208974
E13: 11 | F13: =E13*$B$2 -> 11 | G13: =MAX(0,IF(N13>=1,J13*$B$4*$B$2*(N13-1),0)) -> 6.0436795 | H13: =H12+(G12-I12) -> 416.16173 | I13: =H13*$B$5*$B$2*MAX(0,1-N13) -> 0 | J13: =IF(MOD(F13,3)=0,$B$6+$B$6*$B$12,IF(MOD(F13,7)=0,$B$6-$B$6*$B$12,$B$6)) -> 1000 | K13: =MIN($B$11,J13/H13) -> 2.402912 | L13: =$B$8*(J13/(H13*K13)) -> 50 | M13: =K13*L13 -> 120.1456 | N13: =M13/$B$10 -> 1.201456
E14: 12 | F14: =E14*$B$2 -> 12 | G14: =MAX(0,IF(N14>=1,J14*$B$4*$B$2*(N14-1),0)) -> 5.5277305 | H14: =H13+(G13-I13) -> 422.20541 | I14: =H14*$B$5*$B$2*MAX(0,1-N14) -> 0 | J14: =IF(MOD(F14,3)=0,$B$6+$B$6*$B$12,IF(MOD(F14,7)=0,$B$6-$B$6*$B$12,$B$6)) -> 1000 | K14: =MIN($B$11,J14/H14) -> 2.3685154 | L14: =$B$8*(J14/(H14*K14)) -> 50 | M14: =K14*L14 -> 118.42577 | N14: =M14/$B$10 -> 1.1842577
E15: 13 | F15: =E15*$B$2 -> 13 | G15: =MAX(0,IF(N15>=1,J15*$B$4*$B$2*(N15-1),0)) -> 5.0685944 | H15: =H14+(G14-I14) -> 427.73314 | I15: =H15*$B$5*$B$2*MAX(0,1-N15) -> 0 | J15: =IF(MOD(F15,3)=0,$B$6+$B$6*$B$12,IF(MOD(F15,7)=0,$B$6-$B$6*$B$12,$B$6)) -> 1000 | K15: =MIN($B$11,J15/H15) -> 2.3379063 | L15: =$B$8*(J15/(H15*K15)) -> 50 | M15: =K15*L15 -> 116.89531 | N15: =M15/$B$10 -> 1.1689531
E16: 14 | F16: =E16*$B$2 -> 14 | G16: =MAX(0,IF(N16>=1,J16*$B$4*$B$2*(N16-1),0)) -> 4.6579018 | H16: =H15+(G15-I15) -> 432.80173 | I16: =H16*$B$5*$B$2*MAX(0,1-N16) -> 0 | J16: =IF(MOD(F16,3)=0,$B$6+$B$6*$B$12,IF(MOD(F16,7)=0,$B$6-$B$6*$B$12,$B$6)) -> 1000 | K16: =MIN($B$11,J16/H16) -> 2.3105268 | L16: =$B$8*(J16/(H16*K16)) -> 50 | M16: =K16*L16 -> 115.52634 | N16: =M16/$B$10 -> 1.1552634
E17: 15 | F17: =E17*$B$2 -> 15 | G17: =MAX(0,IF(N17>=1,J17*$B$4*$B$2*(N17-1),0)) -> 4.2888778 | H17: =H16+(G16-I16) -> 437.45964 | I17: =H17*$B$5*$B$2*MAX(0,1-N17) -> 0 | J17: =IF(MOD(F17,3)=0,$B$6+$B$6*$B$12,IF(MOD(F17,7)=0,$B$6-$B$6*$B$12,$B$6)) -> 1000 | K17: =MIN($B$11,J17/H17) -> 2.2859252 | L17: =$B$8*(J17/(H17*K17)) -> 50 | M17: =K17*L17 -> 114.29626 | N17: =M17/$B$10 -> 1.1429626
E18: 16 | F18: =E18*$B$2 -> 16 | G18: =MAX(0,IF(N18>=1,J18*$B$4*$B$2*(N18-1),0)) -> 3.9559716 | H18: =H17+(G17-I17) -> 441.74851 | I18: =H18*$B$5*$B$2*MAX(0,1-N18) -> 0 | J18: =IF(MOD(F18,3)=0,$B$6+$B$6*$B$12,IF(MOD(F18,7)=0,$B$6-$B$6*$B$12,$B$6)) -> 1000 | K18: =MIN($B$11,J18/H18) -> 2.2637314 | L18: =$B$8*(J18/(H18*K18)) -> 50 | M18: =K18*L18 -> 113.18657 | N18: =M18/$B$10 -> 1.1318657
E19: 17 | F19: =E19*$B$2 -> 17 | G19: =MAX(0,IF(N19>=1,J19*$B$4*$B$2*(N19-1),0)) -> 3.6545861 | H19: =H18+(G18-I18) -> 445.70449 | I19: =H19*$B$5*$B$2*MAX(0,1-N19) -> 0 | J19: =IF(MOD(F19,3)=0,$B$6+$B$6*$B$12,IF(MOD(F19,7)=0,$B$6-$B$6*$B$12,$B$6)) -> 1000 | K19: =MIN($B$11,J19/H19) -> 2.2436391 | L19: =$B$8*(J19/(H19*K19)) -> 50 | M19: =K19*L19 -> 112.18195 | N19: =M19/$B$10 -> 1.1218195
E20: 18 | F20: =E20*$B$2 -> 18 | G20: =MAX(0,IF(N20>=1,J20*$B$4*$B$2*(N20-1),0)) -> 3.3808772 | H20: =H19+(G19-I19) -> 449.35907 | I20: =H20*$B$5*$B$2*MAX(0,1-N20) -> 0 | J20: =IF(MOD(F20,3)=0,$B$6+$B$6*$B$12,IF(MOD(F20,7)=0,$B$6-$B$6*$B$12,$B$6)) -> 1000 | K20: =MIN($B$11,J20/H20) -> 2.2253918 | L20: =$B$8*(J20/(H20*K20)) -> 50 | M20: =K20*L20 -> 111.26959 | N20: =M20/$B$10 -> 1.1126959
E21: 19 | F21: =E21*$B$2 -> 19 | G21: =MAX(0,IF(N21>=1,J21*$B$4*$B$2*(N21-1),0)) -> 3.1316025 | H21: =H20+(G20-I20) -> 452.73995 | I21: =H21*$B$5*$B$2*MAX(0,1-N21) -> 0 | J21: =IF(MOD(F21,3)=0,$B$6+$B$6*$B$12,IF(MOD(F21,7)=0,$B$6-$B$6*$B$12,$B$6)) -> 1000 | K21: =MIN($B$11,J21/H21) -> 2.2087735 | L21: =$B$8*(J21/(H21*K21)) -> 50 | M21: =K21*L21 -> 110.43867 | N21: =M21/$B$10 -> 1.1043867
E22: 20 | F22: =E22*$B$2 -> 20 | G22: =MAX(0,IF(N22>=1,J22*$B$4*$B$2*(N22-1),0)) -> 2.9040054 | H22: =H21+(G21-I21) -> 455.87155 | I22: =H22*$B$5*$B$2*MAX(0,1-N22) -> 0 | J22: =IF(MOD(F22,3)=0,$B$6+$B$6*$B$12,IF(MOD(F22,7)=0,$B$6-$B$6*$B$12,$B$6)) -> 1000 | K22: =MIN($B$11,J22/H22) -> 2.1936004 | L22: =$B$8*(J22/(H22*K22)) -> 50 | M22: =K22*L22 -> 109.68002 | N22: =M22/$B$10 -> 1.0968002
E23: 21 | F23: =E23*$B$2 -> 21 | G23: =MAX(0,IF(N23>=1,J23*$B$4*$B$2*(N23-1),0)) -> 2.6957262 | H23: =H22+(G22-I22) -> 458.77556 | I23: =H23*$B$5*$B$2*MAX(0,1-N23) -> 0 | J23: =IF(MOD(F23,3)=0,$B$6+$B$6*$B$12,IF(MOD(F23,7)=0,$B$6-$B$6*$B$12,$B$6)) -> 1000 | K23: =MIN($B$11,J23/H23) -> 2.1797151 | L23: =$B$8*(J23/(H23*K23)) -> 50 | M23: =K23*L23 -> 108.98575 | N23: =M23/$B$10 -> 1.0898575
E24: 22 | F24: =E24*$B$2 -> 22 | G24: =MAX(0,IF(N24>=1,J24*$B$4*$B$2*(N24-1),0)) -> 2.5047312 | H24: =H23+(G23-I23) -> 461.47128 | I24: =H24*$B$5*$B$2*MAX(0,1-N24) -> 0 | J24: =IF(MOD(F24,3)=0,$B$6+$B$6*$B$12,IF(MOD(F24,7)=0,$B$6-$B$6*$B$12,$B$6)) -> 1000 | K24: =MIN($B$11,J24/H24) -> 2.1669821 | L24: =$B$8*(J24/(H24*K24)) -> 50 | M24: =K24*L24 -> 108.3491 | N24: =M24/$B$10 -> 1.083491
... E202: 200 | F202: =E202*$B$2 -> 200 | G202: =MAX(0,IF(N202>=1,J202*$B$4*$B$2*(N202-1),0)) -> 3.5078837e-05 | H202: =H201+(G201-I201) -> 499.99942 | I202: =H202*$B$5*$B$2*MAX(0,1-N202) -> 0 | J202: =IF(MOD(F202,3)=0,$B$6+$B$6*$B$12,IF(MOD(F202,7)=0,$B$6-$B$6*$B$12,$B$6)) -> 1000 | K202: =MIN($B$11,J202/H202) -> 2.0000023 | L202: =$B$8*(J202/(H202*K202)) -> 50 | M202: =K202*L202 -> 100.00012 | N202: =M202/$B$10 -> 1.0000012

Sheet Model_2
A1: Limits to growth with a step-by-step change of demand | G1: Entry flow, car/ hour | H1: Number of cars_2, car | I1: Exit flow, car/ hour | J1: Number of passengers_2, people | K1: Rides per hour, ride/ hour | L1: Price per ride, $ | M1: Hourly incom per car_2, $/ hour | N1: Job attractiveness
A2: TIME STEP | B2: =Model_1!B2 -> 1 | C2: hour | E2: 0 | F2: =E2*$B$2 -> 0 | G2: 0 | H2: =B3 -> 300 | I2: 0 | J2: =B6 -> 1000 | K2: 0 | L2: 0 | M2: =K2*L2 -> 0 | N2: =M2/$B$10 -> 0
A3: Initial number of cars | B3: =Model_1!B3 -> 300 | C3: car | E3: 1 | F3: =E3*$B$2 -> 1 | G3: =MAX(0,IF(N3>=1,J3*$B$4*$B$2*(N3-1),0)) -> 20 | H3: =H2+(G2-I2) -> 300 | I3: =H3*$B$5*$B$2*MAX(0,1-N3) -> 0 | J3: =IF(MOD(F3,3)=0,$B$6+$B$6*$B$12,IF(MOD(F3,7)=0,$B$6-$B$6*$B$12,$B$6)) -> 1000 | K3: =MIN($B$11,J3/H3) -> 3 | L3: =$B$8*(J3/(H3*K3)) -> 55.555556 | M3: =K3*L3 -> 166.66667 | N3: =M3/$B$10 -> 1.6666667
A4: Entry rate | B4: =Model_1!B4 -> 0.03 | C4: car/ hour | E4: 2 | F4: =E4*$B$2 -> 2 | G4: =MAX(0,IF(N4>=1,J4*$B$4*$B$2*(N4-1),0)) -> 16.875 | H4: =H3+(G3-I3) -> 320 | I4: =H4*$B$5*$B$2*MAX(0,1-N4) -> 0 | J4: =IF(MOD(F4,3)=0,$B$6+$B$6*$B$12,IF(MOD(F4,7)=0,$B$6-$B$6*$B$12,$B$6)) -> 1000 | K4: =MIN($B$11,J4/H4) -> 3 | L4: =$B$8*(J4/(H4*K4)) -> 52.083333 | M4: =K4*L4 -> 156.25 | N4: =M4/$B$10 -> 1.5625
A5: Exit rate | B5: =Model_1!B5 -> 0.04 | C5: car/ hour | E5: 3 | F5: =E5*$B$2 -> 3 | G5: =MAX(0,IF(N5>=1,J5*$B$4*$B$2*(N5-1),0)) -> 65.988868 | H5: =H4+(G4-I4) -> 336.875 | I5: =H5*$B$5*$B$2*MAX(0,1-N5) -> 0 | J5: =IF(MOD(F5,3)=0,$B$6+$B$6*$B$12,IF(MOD(F5,7)=0,$B$6-$B$6*$B$12,$B$6)) -> 1600 | K5: =MIN($B$11,J5/H5) -> 3 | L5: =$B$8*(J5/(H5*K5)) -> 79.158936 | M5: =K5*L5 -> 237.47681 | N5: =M5/$B$10 -> 2.3747681
A6: Initial number of passengers | B6: =Model_1!B6 -> 1000 | C6: people | E6: 4 | F6: =E6*$B$2 -> 4 | G6: =MAX(0,IF(N6>=1,J6*$B$4*$B$2*(N6-1),0)) -> 7.233421 | H6: =H5+(G5-I5) -> 402.86387 | I6: =H6*$B$5*$B$2*MAX(0,1-N6) -> 0 | J6: =IF(MOD(F6,3)=0,$B$6+$B$6*$B$12,IF(MOD(F6,7)=0,$B$6-$B$6*$B$12,$B$6)) -> 1000 | K6: =MIN($B$11,J6/H6) -> 2.4822281 | L6: =$B$8*(J6/(H6*K6)) -> 50 | M6: =K6*L6 -> 124.1114 | N6: =M6/$B$10 -> 1.241114
A7: Average taxi ride time | B7: =Model_1!B7 -> 0.33333333 | C7: hour | E7: 5 | F7: =E7*$B$2 -> 5 | G7: =MAX(0,IF(N7>=1,J7*$B$4*$B$2*(N7-1),0)) -> 6.5766865 | H7: =H6+(G6-I6) -> 410.09729 | I7: =H7*$B$5*$B$2*MAX(0,1-N7) -> 0 | J7: =IF(MOD(F7,3)=0,$B$6+$B$6*$B$12,IF(MOD(F7,7)=0,$B$6-$B$6*$B$12,$B$6)) -> 1000 | K7: =MIN($B$11,J7/H7) -> 2.4384458 | L7: =$B$8*(J7/(H7*K7)) -> 50 | M7: =K7*L7 -> 121.92229 | N7: =M7/$B$10 -> 1.2192229
A8: Price of 1 taxi ride | B8: =Model_1!B8 -> 50 | C8: $ | E8: 6 | F8: =E8*$B$2 -> 6 | G8: =MAX(0,IF(N8>=1,J8*$B$4*$B$2*(N8-1),0)) -> 44.158383 | H8: =H7+(G7-I7) -> 416.67398 | I8: =H8*$B$5*$B$2*MAX(0,1-N8) -> 0 | J8: =IF(MOD(F8,3)=0,$B$6+$B$6*$B$12,IF(MOD(F8,7)=0,$B$6-$B$6*$B$12,$B$6)) -> 1600 | K8: =MIN($B$11,J8/H8) -> 3 | L8: =$B$8*(J8/(H8*K8)) -> 63.998877 | M8: =K8*L8 -> 191.99663 | N8: =M8/$B$10 -> 1.9199663
A9: Waiting time | B9: =Model_1!B9 -> 0.083333333 | C9: hour | E9: 7 | F9: =E9*$B$2 -> 7 | G9: =MAX(0,IF(N9>=1,J9*$B$4*$B$2*(N9-1),0)) -> 0 | H9: =H8+(G8-I8) -> 460.83236 | I9: =H9*$B$5*$B$2*MAX(0,1-N9) -> 10.433294 | J9: =IF(MOD(F9,3)=0,$B$6+$B$6*$B$12,IF(MOD(F9,7)=0,$B$6-$B$6*$B$12,$B$6)) -> 400 | K9: =MIN($B$11,J9/H9) -> 0.8679946 | L9: =$B$8*(J9/(H9*K9)) -> 50 | M9: =K9*L9 -> 43.39973 | N9: =M9/$B$10 -> 0.4339973
A10: Target incom (2 rides for 50$ each) | B10: =Model_1!B10 -> 100 | C10: $/hour | E10: 8 | F10: =E10*$B$2 -> 8 | G10: =MAX(0,IF(N10>=1,J10*$B$4*$B$2*(N10-1),0)) -> 3.3037992 | H10: =H9+(G9-I9) -> 450.39906 | I10: =H10*$B$5*$B$2*MAX(0,1-N10) -> 0 | J10: =IF(MOD(F10,3)=0,$B$6+$B$6*$B$12,IF(MOD(F10,7)=0,$B$6-$B$6*$B$12,$B$6)) -> 1000 | K10: =MIN($B$11,J10/H10) -> 2.2202533 | L10: =$B$8*(J10/(H10*K10)) -> 50 | M10: =K10*L10 -> 111.01266 | N10: =M10/$B$10 -> 1.1101266
A11: Max rides per hour | B11: =Model_1!B11 -> 3 | C11: ride/ hour | E11: 9 | F11: =E11*$B$2 -> 9 | G11: =MAX(0,IF(N11>=1,J11*$B$4*$B$2*(N11-1),0)) -> 36.636891 | H11: =H10+(G10-I10) -> 453.70286 | I11: =H11*$B$5*$B$2*MAX(0,1-N11) -> 0 | J11: =IF(MOD(F11,3)=0,$B$6+$B$6*$B$12,IF(MOD(F11,7)=0,$B$6-$B$6*$B$12,$B$6)) -> 1600 | K11: =MIN($B$11,J11/H11) -> 3 | L11: =$B$8*(J11/(H11*K11)) -> 58.775619 | M11: =K11*L11 -> 176.32686 | N11: =M11/$B$10 -> 1.7632686
A12: Demand variation | B12: 0.6 | E12: 10 | F12: =E12*$B$2 -> 10 | G12: =MAX(0,IF(N12>=1,J12*$B$4*$B$2*(N12-1),0)) -> 0.59103374 | H12: =H11+(G11-I11) -> 490.33976 | I12: =H12*$B$5*$B$2*MAX(0,1-N12) -> 0 | J12: =IF(MOD(F12,3)=0,$B$6+$B$6*$B$12,IF(MOD(F12,7)=0,$B$6-$B$6*$B$12,$B$6)) -> 1000 | K12: =MIN($B$11,J12/H12) -> 2.0394022 | L12: =$B$8*(J12/(H12*K12)) -> 50 | M12: =K12*L12 -> 101.97011 | N12: =M12/$B$10 -> 1.0197011
E13: 11 | F13: =E13*$B$2 -> 11 | G13: =MAX(0,IF(N13>=1,J13*$B$4*$B$2*(N13-1),0)) -> 0.55420506 | H13: =H12+(G12-I12) -> 490.93079 | I13: =H13*$B$5*$B$2*MAX(0,1-N13) -> 0 | J13: =IF(MOD(F13,3)=0,$B$6+$B$6*$B$12,IF(MOD(F13,7)=0,$B$6-$B$6*$B$12,$B$6)) -> 1000 | K13: =MIN($B$11,J13/H13) -> 2.036947 | L13: =$B$8*(J13/(H13*K13)) -> 50 | M13: =K13*L13 -> 101.84735 | N13: =M13/$B$10 -> 1.0184735
E14: 12 | F14: =E14*$B$2 -> 12 | G14: =MAX(0,IF(N14>=1,J14*$B$4*$B$2*(N14-1),0)) -> 30.130564 | H14: =H13+(G13-I13) -> 491.48499 | I14: =H14*$B$5*$B$2*MAX(0,1-N14) -> 0 | J14: =IF(MOD(F14,3)=0,$B$6+$B$6*$B$12,IF(MOD(F14,7)=0,$B$6-$B$6*$B$12,$B$6)) -> 1600 | K14: =MIN($B$11,J14/H14) -> 3 | L14: =$B$8*(J14/(H14*K14)) -> 54.257336 | M14: =K14*L14 -> 162.77201 | N14: =M14/$B$10 -> 1.6277201
E15: 13 | F15: =E15*$B$2 -> 13 | G15: =MAX(0,IF(N15>=1,J15*$B$4*$B$2*(N15-1),0)) -> 0 | H15: =H14+(G14-I14) -> 521.61556 | I15: =H15*$B$5*$B$2*MAX(0,1-N15) -> 0.86462234 | J15: =IF(MOD(F15,3)=0,$B$6+$B$6*$B$12,IF(MOD(F15,7)=0,$B$6-$B$6*$B$12,$B$6)) -> 1000 | K15: =MIN($B$11,J15/H15) -> 1.9171207 | L15: =$B$8*(J15/(H15*K15)) -> 50 | M15: =K15*L15 -> 95.856036 | N15: =M15/$B$10 -> 0.95856036
E16: 14 | F16: =E16*$B$2 -> 14 | G16: =MAX(0,IF(N16>=1,J16*$B$4*$B$2*(N16-1),0)) -> 0 | H16: =H15+(G15-I15) -> 520.75094 | I16: =H16*$B$5*$B$2*MAX(0,1-N16) -> 12.830037 | J16: =IF(MOD(F16,3)=0,$B$6+$B$6*$B$12,IF(MOD(F16,7)=0,$B$6-$B$6*$B$12,$B$6)) -> 400 | K16: =MIN($B$11,J16/H16) -> 0.76812152 | L16: =$B$8*(J16/(H16*K16)) -> 50 | M16: =K16*L16 -> 38.406076 | N16: =M16/$B$10 -> 0.38406076
E17: 15 | F17: =E17*$B$2 -> 15 | G17: =MAX(0,IF(N17>=1,J17*$B$4*$B$2*(N17-1),0)) -> 27.602323 | H17: =H16+(G16-I16) -> 507.9209 | I17: =H17*$B$5*$B$2*MAX(0,1-N17) -> 0 | J17: =IF(MOD(F17,3)=0,$B$6+$B$6*$B$12,IF(MOD(F17,7)=0,$B$6-$B$6*$B$12,$B$6)) -> 1600 | K17: =MIN($B$11,J17/H17) -> 3 | L17: =$B$8*(J17/(H17*K17)) -> 52.501613 | M17: =K17*L17 -> 157.50484 | N17: =M17/$B$10 -> 1.5750484
E18: 16 | F18: =E18*$B$2 -> 16 | G18: =MAX(0,IF(N18>=1,J18*$B$4*$B$2*(N18-1),0)) -> 0 | H18: =H17+(G17-I17) -> 535.52322 | I18: =H18*$B$5*$B$2*MAX(0,1-N18) -> 1.4209289 | J18: =IF(MOD(F18,3)=0,$B$6+$B$6*$B$12,IF(MOD(F18,7)=0,$B$6-$B$6*$B$12,$B$6)) -> 1000 | K18: =MIN($B$11,J18/H18) -> 1.8673327 | L18: =$B$8*(J18/(H18*K18)) -> 50 | M18: =K18*L18 -> 93.366633 | N18: =M18/$B$10 -> 0.93366633
E19: 17 | F19: =E19*$B$2 -> 17 | G19: =MAX(0,IF(N19>=1,J19*$B$4*$B$2*(N19-1),0)) -> 0 | H19: =H18+(G18-I18) -> 534.10229 | I19: =H19*$B$5*$B$2*MAX(0,1-N19) -> 1.3640917 | J19: =IF(MOD(F19,3)=0,$B$6+$B$6*$B$12,IF(MOD(F19,7)=0,$B$6-$B$6*$B$12,$B$6)) -> 1000 | K19: =MIN($B$11,J19/H19) -> 1.8723005 | L19: =$B$8*(J19/(H19*K19)) -> 50 | M19: =K19*L19 -> 93.615026 | N19: =M19/$B$10 -> 0.93615026
E20: 18 | F20: =E20*$B$2 -> 18 | G20: =MAX(0,IF(N20>=1,J20*$B$4*$B$2*(N20-1),0)) -> 24.080433 | H20: =H19+(G19-I19) -> 532.7382 | I20: =H20*$B$5*$B$2*MAX(0,1-N20) -> 0 | J20: =IF(MOD(F20,3)=0,$B$6+$B$6*$B$12,IF(MOD(F20,7)=0,$B$6-$B$6*$B$12,$B$6)) -> 1600 | K20: =MIN($B$11,J20/H20) -> 3 | L20: =$B$8*(J20/(H20*K20)) -> 50.055856 | M20: =K20*L20 -> 150.16757 | N20: =M20/$B$10 -> 1.5016757
E21: 19 | F21: =E21*$B$2 -> 19 | G21: =MAX(0,IF(N21>=1,J21*$B$4*$B$2*(N21-1),0)) -> 0 | H21: =H20+(G20-I20) -> 556.81863 | I21: =H21*$B$5*$B$2*MAX(0,1-N21) -> 2.2727454 | J21: =IF(MOD(F21,3)=0,$B$6+$B$6*$B$12,IF(MOD(F21,7)=0,$B$6-$B$6*$B$12,$B$6)) -> 1000 | K21: =MIN($B$11,J21/H21) -> 1.7959169 | L21: =$B$8*(J21/(H21*K21)) -> 50 | M21: =K21*L21 -> 89.795845 | N21: =M21/$B$10 -> 0.89795845
E22: 20 | F22: =E22*$B$2 -> 20 | G22: =MAX(0,IF(N22>=1,J22*$B$4*$B$2*(N22-1),0)) -> 0 | H22: =H21+(G21-I21) -> 554.54589 | I22: =H22*$B$5*$B$2*MAX(0,1-N22) -> 2.1818355 | J22: =IF(MOD(F22,3)=0,$B$6+$B$6*$B$12,IF(MOD(F22,7)=0,$B$6-$B$6*$B$12,$B$6)) -> 1000 | K22: =MIN($B$11,J22/H22) -> 1.8032773 | L22: =$B$8*(J22/(H22*K22)) -> 50 | M22: =K22*L22 -> 90.163864 | N22: =M22/$B$10 -> 0.90163864
E23: 21 | F23: =E23*$B$2 -> 21 | G23: =MAX(0,IF(N23>=1,J23*$B$4*$B$2*(N23-1),0)) -> 21.519368 | H23: =H22+(G22-I22) -> 552.36405 | I23: =H23*$B$5*$B$2*MAX(0,1-N23) -> 0 | J23: =IF(MOD(F23,3)=0,$B$6+$B$6*$B$12,IF(MOD(F23,7)=0,$B$6-$B$6*$B$12,$B$6)) -> 1600 | K23: =MIN($B$11,J23/H23) -> 2.8966403 | L23: =$B$8*(J23/(H23*K23)) -> 50 | M23: =K23*L23 -> 144.83202 | N23: =M23/$B$10 -> 1.4483202
E24: 22 | F24: =E24*$B$2 -> 22 | G24: =MAX(0,IF(N24>=1,J24*$B$4*$B$2*(N24-1),0)) -> 0 | H24: =H23+(G23-I23) -> 573.88342 | I24: =H24*$B$5*$B$2*MAX(0,1-N24) -> 2.9553369 | J24: =IF(MOD(F24,3)=0,$B$6+$B$6*$B$12,IF(MOD(F24,7)=0,$B$6-$B$6*$B$12,$B$6)) -> 1000 | K24: =MIN($B$11,J24/H24) -> 1.7425142 | L24: =$B$8*(J24/(H24*K24)) -> 50 | M24: =K24*L24 -> 87.125709 | N24: =M24/$B$10 -> 0.87125709
... E202: 200 | F202: =E202*$B$2 -> 200 | G202: =MAX(0,IF(N202>=1,J202*$B$4*$B$2*(N202-1),0)) -> 0 | H202: =H201+(G201-I201) -> 626.78397 | I202: =H202*$B$5*$B$2*MAX(0,1-N202) -> 5.0713589 | J202: =IF(MOD(F202,3)=0,$B$6+$B$6*$B$12,IF(MOD(F202,7)=0,$B$6-$B$6*$B$12,$B$6)) -> 1000 | K202: =MIN($B$11,J202/H202) -> 1.595446 | L202: =$B$8*(J202/(H202*K202)) -> 50 | M202: =K202*L202 -> 79.772302 | N202: =M202/$B$10 -> 0.79772302

Sheet Model_3
A1: Limits to growth with delayed entry time and step-by-step change of demand | G1: Entry flow, car/ hour | H1: Number of cars_3, car | I1: Exit flow, car/ hour | J1: Number of passengers_3, people | K1: Rides per hour, ride/ hour | L1: Price per ride, $ | M1: Hourly incom per car_3, $/ hour | N1: Job attractiveness
A2: TIME STEP | B2: =Model_1!B2 -> 1 | C2: hour | E2: 0 | F2: =E2*$B$2 -> 0 | G2: 0 | H2: =B3 -> 300 | I2: 0 | J2: =B6 -> 1000 | K2: 0 | L2: 0 | M2: =K2*L2 -> 0 | N2: =M2/$B$10 -> 0
A3: Initial number of cars | B3: =Model_1!B3 -> 300 | C3: car | E3: 1 | F3: =E3*$B$2 -> 1 | G3: 0 | H3: =H2+(G2-I2) -> 300 | I3: =H3*$B$5*$B$2*MAX(0,1-N3) -> 0 | J3: =IF(MOD(F3,3)=0,$B$6+$B$6*$B$12,IF(MOD(F3,7)=0,$B$6-$B$6*$B$12,$B$6)) -> 1000 | K3: =MIN($B$11,J3/H3) -> 3 | L3: =$B$8*(J3/(H3*K3)) -> 55.555556 | M3: =K3*L3 -> 166.66667 | N3: =M3/$B$10 -> 1.6666667
A4: Entry rate | B4: =Model_1!B4 -> 0.03 | C4: car/ hour | E4: 2 | F4: =E4*$B$2 -> 2 | G4: 0 | H4: =H3+(G3-I3) -> 300 | I4: =H4*$B$5*$B$2*MAX(0,1-N4) -> 0 | J4: =IF(MOD(F4,3)=0,$B$6+$B$6*$B$12,IF(MOD(F4,7)=0,$B$6-$B$6*$B$12,$B$6)) -> 1000 | K4: =MIN($B$11,J4/H4) -> 3 | L4: =$B$8*(J4/(H4*K4)) -> 55.555556 | M4: =K4*L4 -> 166.66667 | N4: =M4/$B$10 -> 1.6666667
A5: Exit rate | B5: =Model_1!B5 -> 0.04 | C5: car/ hour | E5: 3 | F5: =E5*$B$2 -> 3 | G5: 0 | H5: =H4+(G4-I4) -> 300 | I5: =H5*$B$5*$B$2*MAX(0,1-N5) -> 0 | J5: =IF(MOD(F5,3)=0,$B$6+$B$6*$B$12,IF(MOD(F5,7)=0,$B$6-$B$6*$B$12,$B$6)) -> 1600 | K5: =MIN($B$11,J5/H5) -> 3 | L5: =$B$8*(J5/(H5*K5)) -> 88.888889 | M5: =K5*L5 -> 266.66667 | N5: =M5/$B$10 -> 2.6666667
A6: Initial number of passengers | B6: =Model_1!B6 -> 1000 | C6: people | E6: 4 | F6: =E6*$B$2 -> 4 | G6: 0 | H6: =H5+(G5-I5) -> 300 | I6: =H6*$B$5*$B$2*MAX(0,1-N6) -> 0 | J6: =IF(MOD(F6,3)=0,$B$6+$B$6*$B$12,IF(MOD(F6,7)=0,$B$6-$B$6*$B$12,$B$6)) -> 1000 | K6: =MIN($B$11,J6/H6) -> 3 | L6: =$B$8*(J6/(H6*K6)) -> 55.555556 | M6: =K6*L6 -> 166.66667 | N6: =M6/$B$10 -> 1.6666667
A7: Average taxi ride time | B7: =Model_1!B7 -> 0.33333333 | C7: hour | E7: 5 | F7: =E7*$B$2 -> 5 | G7: =MAX(0,IF(OFFSET(N7,-$B$13,0)>=1,J7*$B$4*$B$2*(OFFSET(N7,-$B$13,0)-1),0)) -> 0 | H7: =H6+(G6-I6) -> 300 | I7: =H7*$B$5*$B$2*MAX(0,1-N7) -> 0 | J7: =IF(MOD(F7,3)=0,$B$6+$B$6*$B$12,IF(MOD(F7,7)=0,$B$6-$B$6*$B$12,$B$6)) -> 1000 | K7: =MIN($B$11,J7/H7) -> 3 | L7: =$B$8*(J7/(H7*K7)) -> 55.555556 | M7: =K7*L7 -> 166.66667 | N7: =M7/$B$10 -> 1.6666667
A8: Price of 1 taxi ride | B8: =Model_1!B8 -> 50 | C8: $ | E8: 6 | F8: =E8*$B$2 -> 6 | G8: =MAX(0,IF(OFFSET(N8,-$B$13,0)>=1,J8*$B$4*$B$2*(OFFSET(N8,-$B$13,0)-1),0)) -> 32 | H8: =H7+(G7-I7) -> 300 | I8: =H8*$B$5*$B$2*MAX(0,1-N8) -> 0 | J8: =IF(MOD(F8,3)=0,$B$6+$B$6*$B$12,IF(MOD(F8,7)=0,$B$6-$B$6*$B$12,$B$6)) -> 1600 | K8: =MIN($B$11,J8/H8) -> 3 | L8: =$B$8*(J8/(H8*K8)) -> 88.888889 | M8: =K8*L8 -> 266.66667 | N8: =M8/$B$10 -> 2.6666667
A9: Waiting time | B9: =Model_1!B9 -> 0.083333333 | C9: hour | E9: 7 | F9: =E9*$B$2 -> 7 | G9: =MAX(0,IF(OFFSET(N9,-$B$13,0)>=1,J9*$B$4*$B$2*(OFFSET(N9,-$B$13,0)-1),0)) -> 8 | H9: =H8+(G8-I8) -> 332 | I9: =H9*$B$5*$B$2*MAX(0,1-N9) -> 5.28 | J9: =IF(MOD(F9,3)=0,$B$6+$B$6*$B$12,IF(MOD(F9,7)=0,$B$6-$B$6*$B$12,$B$6)) -> 400 | K9: =MIN($B$11,J9/H9) -> 1.2048193 | L9: =$B$8*(J9/(H9*K9)) -> 50 | M9: =K9*L9 -> 60.240964 | N9: =M9/$B$10 -> 0.60240964
A10: Target incom (2 rides for 50$ each) | B10: =Model_1!B10 -> 100 | C10: $/hour | E10: 8 | F10: =E10*$B$2 -> 8 | G10: =MAX(0,IF(OFFSET(N10,-$B$13,0)>=1,J10*$B$4*$B$2*(OFFSET(N10,-$B$13,0)-1),0)) -> 50 | H10: =H9+(G9-I9) -> 334.72 | I10: =H10*$B$5*$B$2*MAX(0,1-N10) -> 0 | J10: =IF(MOD(F10,3)=0,$B$6+$B$6*$B$12,IF(MOD(F10,7)=0,$B$6-$B$6*$B$12,$B$6)) -> 1000 | K10: =MIN($B$11,J10/H10) -> 2.9875717 | L10: =$B$8*(J10/(H10*K10)) -> 50 | M10: =K10*L10 -> 149.37859 | N10: =M10/$B$10 -> 1.4937859
A11: Max rides per hour | B11: =Model_1!B11 -> 3 | C11: ride/ hour | E11: 9 | F11: =E11*$B$2 -> 9 | G11: =MAX(0,IF(OFFSET(N11,-$B$13,0)>=1,J11*$B$4*$B$2*(OFFSET(N11,-$B$13,0)-1),0)) -> 32 | H11: =H10+(G10-I10) -> 384.72 | I11: =H11*$B$5*$B$2*MAX(0,1-N11) -> 0 | J11: =IF(MOD(F11,3)=0,$B$6+$B$6*$B$12,IF(MOD(F11,7)=0,$B$6-$B$6*$B$12,$B$6)) -> 1600 | K11: =MIN($B$11,J11/H11) -> 3 | L11: =$B$8*(J11/(H11*K11)) -> 69.31448 | M11: =K11*L11 -> 207.94344 | N11: =M11/$B$10 -> 2.0794344
A12: Demand variation | B12: =Model_2!$B$12 -> 0.6 | E12: 10 | F12: =E12*$B$2 -> 10 | G12: =MAX(0,IF(OFFSET(N12,-$B$13,0)>=1,J12*$B$4*$B$2*(OFFSET(N12,-$B$13,0)-1),0)) -> 20 | H12: =H11+(G11-I11) -> 416.72 | I12: =H12*$B$5*$B$2*MAX(0,1-N12) -> 0 | J12: =IF(MOD(F12,3)=0,$B$6+$B$6*$B$12,IF(MOD(F12,7)=0,$B$6-$B$6*$B$12,$B$6)) -> 1000 | K12: =MIN($B$11,J12/H12) -> 2.3996928 | L12: =$B$8*(J12/(H12*K12)) -> 50 | M12: =K12*L12 -> 119.98464 | N12: =M12/$B$10 -> 1.1998464
A13: Entry delay time | B13: 5 | C13: hour | E13: 11 | F13: =E13*$B$2 -> 11 | G13: =MAX(0,IF(OFFSET(N13,-$B$13,0)>=1,J13*$B$4*$B$2*(OFFSET(N13,-$B$13,0)-1),0)) -> 50 | H13: =H12+(G12-I12) -> 436.72 | I13: =H13*$B$5*$B$2*MAX(0,1-N13) -> 0 | J13: =IF(MOD(F13,3)=0,$B$6+$B$6*$B$12,IF(MOD(F13,7)=0,$B$6-$B$6*$B$12,$B$6)) -> 1000 | K13: =MIN($B$11,J13/H13) -> 2.2897967 | L13: =$B$8*(J13/(H13*K13)) -> 50 | M13: =K13*L13 -> 114.48983 | N13: =M13/$B$10 -> 1.1448983
E14: 12 | F14: =E14*$B$2 -> 12 | G14: =MAX(0,IF(OFFSET(N14,-$B$13,0)>=1,J14*$B$4*$B$2*(OFFSET(N14,-$B$13,0)-1),0)) -> 0 | H14: =H13+(G13-I13) -> 486.72 | I14: =H14*$B$5*$B$2*MAX(0,1-N14) -> 0 | J14: =IF(MOD(F14,3)=0,$B$6+$B$6*$B$12,IF(MOD(F14,7)=0,$B$6-$B$6*$B$12,$B$6)) -> 1600 | K14: =MIN($B$11,J14/H14) -> 3 | L14: =$B$8*(J14/(H14*K14)) -> 54.788516 | M14: =K14*L14 -> 164.36555 | N14: =M14/$B$10 -> 1.6436555
E15: 13 | F15: =E15*$B$2 -> 13 | G15: =MAX(0,IF(OFFSET(N15,-$B$13,0)>=1,J15*$B$4*$B$2*(OFFSET(N15,-$B$13,0)-1),0)) -> 14.813576 | H15: =H14+(G14-I14) -> 486.72 | I15: =H15*$B$5*$B$2*MAX(0,1-N15) -> 0 | J15: =IF(MOD(F15,3)=0,$B$6+$B$6*$B$12,IF(MOD(F15,7)=0,$B$6-$B$6*$B$12,$B$6)) -> 1000 | K15: =MIN($B$11,J15/H15) -> 2.0545694 | L15: =$B$8*(J15/(H15*K15)) -> 50 | M15: =K15*L15 -> 102.72847 | N15: =M15/$B$10 -> 1.0272847
E16: 14 | F16: =E16*$B$2 -> 14 | G16: =MAX(0,IF(OFFSET(N16,-$B$13,0)>=1,J16*$B$4*$B$2*(OFFSET(N16,-$B$13,0)-1),0)) -> 12.953213 | H16: =H15+(G15-I15) -> 501.53358 | I16: =H16*$B$5*$B$2*MAX(0,1-N16) -> 12.061343 | J16: =IF(MOD(F16,3)=0,$B$6+$B$6*$B$12,IF(MOD(F16,7)=0,$B$6-$B$6*$B$12,$B$6)) -> 400 | K16: =MIN($B$11,J16/H16) -> 0.79755378 | L16: =$B$8*(J16/(H16*K16)) -> 50 | M16: =K16*L16 -> 39.877689 | N16: =M16/$B$10 -> 0.39877689
E17: 15 | F17: =E17*$B$2 -> 15 | G17: =MAX(0,IF(OFFSET(N17,-$B$13,0)>=1,J17*$B$4*$B$2*(OFFSET(N17,-$B$13,0)-1),0)) -> 9.5926281 | H17: =H16+(G16-I16) -> 502.42545 | I17: =H17*$B$5*$B$2*MAX(0,1-N17) -> 0 | J17: =IF(MOD(F17,3)=0,$B$6+$B$6*$B$12,IF(MOD(F17,7)=0,$B$6-$B$6*$B$12,$B$6)) -> 1600 | K17: =MIN($B$11,J17/H17) -> 3 | L17: =$B$8*(J17/(H17*K17)) -> 53.075868 | M17: =K17*L17 -> 159.2276 | N17: =M17/$B$10 -> 1.592276
E18: 16 | F18: =E18*$B$2 -> 16 | G18: =MAX(0,IF(OFFSET(N18,-$B$13,0)>=1,J18*$B$4*$B$2*(OFFSET(N18,-$B$13,0)-1),0)) -> 4.34695 | H18: =H17+(G17-I17) -> 512.01807 | I18: =H18*$B$5*$B$2*MAX(0,1-N18) -> 0.48072293 | J18: =IF(MOD(F18,3)=0,$B$6+$B$6*$B$12,IF(MOD(F18,7)=0,$B$6-$B$6*$B$12,$B$6)) -> 1000 | K18: =MIN($B$11,J18/H18) -> 1.9530561 | L18: =$B$8*(J18/(H18*K18)) -> 50 | M18: =K18*L18 -> 97.652803 | N18: =M18/$B$10 -> 0.97652803
E19: 17 | F19: =E19*$B$2 -> 17 | G19: =MAX(0,IF(OFFSET(N19,-$B$13,0)>=1,J19*$B$4*$B$2*(OFFSET(N19,-$B$13,0)-1),0)) -> 19.309665 | H19: =H18+(G18-I18) -> 515.8843 | I19: =H19*$B$5*$B$2*MAX(0,1-N19) -> 0.63537202 | J19: =IF(MOD(F19,3)=0,$B$6+$B$6*$B$12,IF(MOD(F19,7)=0,$B$6-$B$6*$B$12,$B$6)) -> 1000 | K19: =MIN($B$11,J19/H19) -> 1.9384191 | L19: =$B$8*(J19/(H19*K19)) -> 50 | M19: =K19*L19 -> 96.920957 | N19: =M19/$B$10 -> 0.96920957
E20: 18 | F20: =E20*$B$2 -> 18 | G20: =MAX(0,IF(OFFSET(N20,-$B$13,0)>=1,J20*$B$4*$B$2*(OFFSET(N20,-$B$13,0)-1),0)) -> 1.3096647 | H20: =H19+(G19-I19) -> 534.55859 | I20: =H20*$B$5*$B$2*MAX(0,1-N20) -> 0 | J20: =IF(MOD(F20,3)=0,$B$6+$B$6*$B$12,IF(MOD(F20,7)=0,$B$6-$B$6*$B$12,$B$6)) -> 1600 | K20: =MIN($B$11,J20/H20) -> 2.9931237 | L20: =$B$8*(J20/(H20*K20)) -> 50 | M20: =K20*L20 -> 149.65619 | N20: =M20/$B$10 -> 1.4965619
E21: 19 | F21: =E21*$B$2 -> 19 | G21: =MAX(0,IF(OFFSET(N21,-$B$13,0)>=1,J21*$B$4*$B$2*(OFFSET(N21,-$B$13,0)-1),0)) -> 0 | H21: =H20+(G20-I20) -> 535.86826 | I21: =H21*$B$5*$B$2*MAX(0,1-N21) -> 1.4347303 | J21: =IF(MOD(F21,3)=0,$B$6+$B$6*$B$12,IF(MOD(F21,7)=0,$B$6-$B$6*$B$12,$B$6)) -> 1000 | K21: =MIN($B$11,J21/H21) -> 1.8661303 | L21: =$B$8*(J21/(H21*K21)) -> 50 | M21: =K21*L21 -> 93.306516 | N21: =M21/$B$10 -> 0.93306516
E22: 20 | F22: =E22*$B$2 -> 20 | G22: =MAX(0,IF(OFFSET(N22,-$B$13,0)>=1,J22*$B$4*$B$2*(OFFSET(N22,-$B$13,0)-1),0)) -> 17.768281 | H22: =H21+(G21-I21) -> 534.43353 | I22: =H22*$B$5*$B$2*MAX(0,1-N22) -> 1.3773411 | J22: =IF(MOD(F22,3)=0,$B$6+$B$6*$B$12,IF(MOD(F22,7)=0,$B$6-$B$6*$B$12,$B$6)) -> 1000 | K22: =MIN($B$11,J22/H22) -> 1.8711401 | L22: =$B$8*(J22/(H22*K22)) -> 50 | M22: =K22*L22 -> 93.557005 | N22: =M22/$B$10 -> 0.93557005
E23: 21 | F23: =E23*$B$2 -> 21 | G23: =MAX(0,IF(OFFSET(N23,-$B$13,0)>=1,J23*$B$4*$B$2*(OFFSET(N23,-$B$13,0)-1),0)) -> 0 | H23: =H22+(G22-I22) -> 550.82447 | I23: =H23*$B$5*$B$2*MAX(0,1-N23) -> 0 | J23: =IF(MOD(F23,3)=0,$B$6+$B$6*$B$12,IF(MOD(F23,7)=0,$B$6-$B$6*$B$12,$B$6)) -> 1600 | K23: =MIN($B$11,J23/H23) -> 2.9047366 | L23: =$B$8*(J23/(H23*K23)) -> 50 | M23: =K23*L23 -> 145.23683 | N23: =M23/$B$10 -> 1.4523683
E24: 22 | F24: =E24*$B$2 -> 22 | G24: =MAX(0,IF(OFFSET(N24,-$B$13,0)>=1,J24*$B$4*$B$2*(OFFSET(N24,-$B$13,0)-1),0)) -> 0 | H24: =H23+(G23-I23) -> 550.82447 | I24: =H24*$B$5*$B$2*MAX(0,1-N24) -> 2.0329787 | J24: =IF(MOD(F24,3)=0,$B$6+$B$6*$B$12,IF(MOD(F24,7)=0,$B$6-$B$6*$B$12,$B$6)) -> 1000 | K24: =MIN($B$11,J24/H24) -> 1.8154604 | L24: =$B$8*(J24/(H24*K24)) -> 50 | M24: =K24*L24 -> 90.773019 | N24: =M24/$B$10 -> 0.90773019
E25: 23 | F25: =E25*$B$2 -> 23 | G25: =MAX(0,IF(OFFSET(N25,-$B$13,0)>=1,J25*$B$4*$B$2*(OFFSET(N25,-$B$13,0)-1),0)) -> 14.896856 | H25: =H24+(G24-I24) -> 548.79149 | I25: =H25*$B$5*$B$2*MAX(0,1-N25) -> 1.9516596 | J25: =IF(MOD(F25,3)=0,$B$6+$B$6*$B$12,IF(MOD(F25,7)=0,$B$6-$B$6*$B$12,$B$6)) -> 1000 | K25: =MIN($B$11,J25/H25) -> 1.8221857 | L25: =$B$8*(J25/(H25*K25)) -> 50 | M25: =K25*L25 -> 91.109285 | N25: =M25/$B$10 -> 0.91109285
... E202: 200 | F202: =E202*$B$2 -> 200 | G202: =MAX(0,IF(OFFSET(N202,-$B$13,0)>=1,J202*$B$4*$B$2*(OFFSET(N202,-$B$13,0)-1),0)) -> 10.41649 | H202: =H201+(G201-I201) -> 582.20538 | I202: =H202*$B$5*$B$2*MAX(0,1-N202) -> 3.2882153 | J202: =IF(MOD(F202,3)=0,$B$6+$B$6*$B$12,IF(MOD(F202,7)=0,$B$6-$B$6*$B$12,$B$6)) -> 1000 | K202: =MIN($B$11,J202/H202) -> 1.7176069 | L202: =$B$8*(J202/(H202*K202)) -> 50 | M202: =K202*L202 -> 85.880347 | N202: =M202/$B$10 -> 0.85880347

Sheet Model_4
A1: Limits to growth with periodic changes of demand | G1: Entry flow, car/ hour | H1: Number of cars_4, car | I1: Exit flow, car/ hour | J1: Number of passengers_4, people | K1: Rides per hour, ride/ hour | L1: Price per ride, $ | M1: Hourly incom per car_4, $/ hour | N1: Job attractiveness
A2: TIME STEP | B2: =Model_1!B2 -> 1 | C2: hour | E2: 0 | F2: =E2*$B$2 -> 0 | G2: 0 | H2: =B3 -> 300 | I2: 0 | J2: =IF(F2<=10,$B$6,IF(F2<=20,$B$6-$B$6*$B$12,IF(F2<=30,$B$6+$B$6*$B$12,IF(F2<=40,$B$6-$B$6*$B$12,IF(F2<=50,$B$6+$B$6*$B$12,IF(F2<=60,$B$6-$B$6*$B$12,IF(F2<=70,$B$6+$B$6*$B$12,IF(F2<=80,$B$6-$B$6*$B$12,IF(F2<=90,$B$6+$B$6*$B$12,IF(F2<=100,$B$6-$B$6*$B$12,IF(F2<=110,$B$6+$B$6*$B$12,IF(F2<=120,$B$6-$B$6*$B$12,IF(F2<=130,$B$6+$B$6*$B$12,IF(F2<=140,$B$6-$B$6*$B$12,IF(F2<=150,$B$6+$B$6*$B$12,IF(F2<=160,$B$6-$B$6*$B$12,IF(F2<=170,$B$6+$B$6*$B$12,IF(F2<=180,$B$6-$B$6*$B$12,IF(F2<=190,$B$6+$B$6*$B$12,IF(F2<=200,$B$6-$B$6*$B$12,$B$6)))))))))))))))))))) -> 1000 | K2: 0 | L2: 0 | M2: =K2*L2 -> 0 | N2: =M2/$B$10 -> 0
A3: Initial number of cars | B3: =Model_1!B3 -> 300 | C3: car | E3: 1 | F3: =E3*$B$2 -> 1 | G3: =MAX(0,IF(N3>=1,J3*$B$4*$B$2*(N3-1),0)) -> 20 | H3: =H2+(G2-I2) -> 300 | I3: =H3*$B$5*$B$2*MAX(0,1-N3) -> 0 | J3: =IF(F3<=10,$B$6,IF(F3<=20,$B$6-$B$6*$B$12,IF(F3<=30,$B$6+$B$6*$B$12,IF(F3<=40,$B$6-$B$6*$B$12,IF(F3<=50,$B$6+$B$6*$B$12,IF(F3<=60,$B$6-$B$6*$B$12,IF(F3<=70,$B$6+$B$6*$B$12,IF(F3<=80,$B$6-$B$6*$B$12,IF(F3<=90,$B$6+$B$6*$B$12,IF(F3<=100,$B$6-$B$6*$B$12,IF(F3<=110,$B$6+$B$6*$B$12,IF(F3<=120,$B$6-$B$6*$B$12,IF(F3<=130,$B$6+$B$6*$B$12,IF(F3<=140,$B$6-$B$6*$B$12,IF(F3<=150,$B$6+$B$6*$B$12,IF(F3<=160,$B$6-$B$6*$B$12,IF(F3<=170,$B$6+$B$6*$B$12,IF(F3<=180,$B$6-$B$6*$B$12,IF(F3<=190,$B$6+$B$6*$B$12,IF(F3<=200,$B$6-$B$6*$B$12,$B$6)))))))))))))))))))) -> 1000 | K3: =MIN($B$11,J3/H3) -> 3 | L3: =$B$8*(J3/(H3*K3)) -> 55.555556 | M3: =K3*L3 -> 166.66667 | N3: =M3/$B$10 -> 1.6666667
A4: Entry rate | B4: =Model_1!B4 -> 0.03 | C4: car/ hour | E4: 2 | F4: =E4*$B$2 -> 2 | G4: =MAX(0,IF(N4>=1,J4*$B$4*$B$2*(N4-1),0)) -> 16.875 | H4: =H3+(G3-I3) -> 320 | I4: =H4*$B$5*$B$2*MAX(0,1-N4) -> 0 | J4: =IF(F4<=10,$B$6,IF(F4<=20,$B$6-$B$6*$B$12,IF(F4<=30,$B$6+$B$6*$B$12,IF(F4<=40,$B$6-$B$6*$B$12,IF(F4<=50,$B$6+$B$6*$B$12,IF(F4<=60,$B$6-$B$6*$B$12,IF(F4<=70,$B$6+$B$6*$B$12,IF(F4<=80,$B$6-$B$6*$B$12,IF(F4<=90,$B$6+$B$6*$B$12,IF(F4<=100,$B$6-$B$6*$B$12,IF(F4<=110,$B$6+$B$6*$B$12,IF(F4<=120,$B$6-$B$6*$B$12,IF(F4<=130,$B$6+$B$6*$B$12,IF(F4<=140,$B$6-$B$6*$B$12,IF(F4<=150,$B$6+$B$6*$B$12,IF(F4<=160,$B$6-$B$6*$B$12,IF(F4<=170,$B$6+$B$6*$B$12,IF(F4<=180,$B$6-$B$6*$B$12,IF(F4<=190,$B$6+$B$6*$B$12,IF(F4<=200,$B$6-$B$6*$B$12,$B$6)))))))))))))))))))) -> 1000 | K4: =MIN($B$11,J4/H4) -> 3 | L4: =$B$8*(J4/(H4*K4)) -> 52.083333 | M4: =K4*L4 -> 156.25 | N4: =M4/$B$10 -> 1.5625
A5: Exit rate | B5: =Model_1!B5 -> 0.04 | C5: car/ hour | E5: 3 | F5: =E5*$B$2 -> 3 | G5: =MAX(0,IF(N5>=1,J5*$B$4*$B$2*(N5-1),0)) -> 14.526902 | H5: =H4+(G4-I4) -> 336.875 | I5: =H5*$B$5*$B$2*MAX(0,1-N5) -> 0 | J5: =IF(F5<=10,$B$6,IF(F5<=20,$B$6-$B$6*$B$12,IF(F5<=30,$B$6+$B$6*$B$12,IF(F5<=40,$B$6-$B$6*$B$12,IF(F5<=50,$B$6+$B$6*$B$12,IF(F5<=60,$B$6-$B$6*$B$12,IF(F5<=70,$B$6+$B$6*$B$12,IF(F5<=80,$B$6-$B$6*$B$12,IF(F5<=90,$B$6+$B$6*$B$12,IF(F5<=100,$B$6-$B$6*$B$12,IF(F5<=110,$B$6+$B$6*$B$12,IF(F5<=120,$B$6-$B$6*$B$12,IF(F5<=130,$B$6+$B$6*$B$12,IF(F5<=140,$B$6-$B$6*$B$12,IF(F5<=150,$B$6+$B$6*$B$12,IF(F5<=160,$B$6-$B$6*$B$12,IF(F5<=170,$B$6+$B$6*$B$12,IF(F5<=180,$B$6-$B$6*$B$12,IF(F5<=190,$B$6+$B$6*$B$12,IF(F5<=200,$B$6-$B$6*$B$12,$B$6)))))))))))))))))))) -> 1000 | K5: =MIN($B$11,J5/H5) -> 2.9684601 | L5: =$B$8*(J5/(H5*K5)) -> 50 | M5: =K5*L5 -> 148.42301 | N5: =M5/$B$10 -> 1.4842301
A6: Initial number of passengers | B6: =Model_1!B6 -> 1000 | C6: people | E6: 4 | F6: =E6*$B$2 -> 4 | G6: =MAX(0,IF(N6>=1,J6*$B$4*$B$2*(N6-1),0)) -> 12.686166 | H6: =H5+(G5-I5) -> 351.4019 | I6: =H6*$B$5*$B$2*MAX(0,1-N6) -> 0 | J6: =IF(F6<=10,$B$6,IF(F6<=20,$B$6-$B$6*$B$12,IF(F6<=30,$B$6+$B$6*$B$12,IF(F6<=40,$B$6-$B$6*$B$12,IF(F6<=50,$B$6+$B$6*$B$12,IF(F6<=60,$B$6-$B$6*$B$12,IF(F6<=70,$B$6+$B$6*$B$12,IF(F6<=80,$B$6-$B$6*$B$12,IF(F6<=90,$B$6+$B$6*$B$12,IF(F6<=100,$B$6-$B$6*$B$12,IF(F6<=110,$B$6+$B$6*$B$12,IF(F6<=120,$B$6-$B$6*$B$12,IF(F6<=130,$B$6+$B$6*$B$12,IF(F6<=140,$B$6-$B$6*$B$12,IF(F6<=150,$B$6+$B$6*$B$12,IF(F6<=160,$B$6-$B$6*$B$12,IF(F6<=170,$B$6+$B$6*$B$12,IF(F6<=180,$B$6-$B$6*$B$12,IF(F6<=190,$B$6+$B$6*$B$12,IF(F6<=200,$B$6-$B$6*$B$12,$B$6)))))))))))))))))))) -> 1000 | K6: =MIN($B$11,J6/H6) -> 2.8457444 | L6: =$B$8*(J6/(H6*K6)) -> 50 | M6: =K6*L6 -> 142.28722 | N6: =M6/$B$10 -> 1.4228722
A7: Average taxi ride time | B7: =Model_1!B7 -> 0.33333333 | C7: hour | E7: 5 | F7: =E7*$B$2 -> 5 | G7: =MAX(0,IF(N7>=1,J7*$B$4*$B$2*(N7-1),0)) -> 11.198823 | H7: =H6+(G6-I6) -> 364.08807 | I7: =H7*$B$5*$B$2*MAX(0,1-N7) -> 0 | J7: =IF(F7<=10,$B$6,IF(F7<=20,$B$6-$B$6*$B$12,IF(F7<=30,$B$6+$B$6*$B$12,IF(F7<=40,$B$6-$B$6*$B$12,IF(F7<=50,$B$6+$B$6*$B$12,IF(F7<=60,$B$6-$B$6*$B$12,IF(F7<=70,$B$6+$B$6*$B$12,IF(F7<=80,$B$6-$B$6*$B$12,IF(F7<=90,$B$6+$B$6*$B$12,IF(F7<=100,$B$6-$B$6*$B$12,IF(F7<=110,$B$6+$B$6*$B$12,IF(F7<=120,$B$6-$B$6*$B$12,IF(F7<=130,$B$6+$B$6*$B$12,IF(F7<=140,$B$6-$B$6*$B$12,IF(F7<=150,$B$6+$B$6*$B$12,IF(F7<=160,$B$6-$B$6*$B$12,IF(F7<=170,$B$6+$B$6*$B$12,IF(F7<=180,$B$6-$B$6*$B$12,IF(F7<=190,$B$6+$B$6*$B$12,IF(F7<=200,$B$6-$B$6*$B$12,$B$6)))))))))))))))))))) -> 1000 | K7: =MIN($B$11,J7/H7) -> 2.7465882 | L7: =$B$8*(J7/(H7*K7)) -> 50 | M7: =K7*L7 -> 137.32941 | N7: =M7/$B$10 -> 1.3732941
A8: Price of 1 taxi ride | B8: =Model_1!B8 -> 50 | C8: $ | E8: 6 | F8: =E8*$B$2 -> 6 | G8: =MAX(0,IF(N8>=1,J8*$B$4*$B$2*(N8-1),0)) -> 9.9694217 | H8: =H7+(G7-I7) -> 375.28689 | I8: =H8*$B$5*$B$2*MAX(0,1-N8) -> 0 | J8: =IF(F8<=10,$B$6,IF(F8<=20,$B$6-$B$6*$B$12,IF(F8<=30,$B$6+$B$6*$B$12,IF(F8<=40,$B$6-$B$6*$B$12,IF(F8<=50,$B$6+$B$6*$B$12,IF(F8<=60,$B$6-$B$6*$B$12,IF(F8<=70,$B$6+$B$6*$B$12,IF(F8<=80,$B$6-$B$6*$B$12,IF(F8<=90,$B$6+$B$6*$B$12,IF(F8<=100,$B$6-$B$6*$B$12,IF(F8<=110,$B$6+$B$6*$B$12,IF(F8<=120,$B$6-$B$6*$B$12,IF(F8<=130,$B$6+$B$6*$B$12,IF(F8<=140,$B$6-$B$6*$B$12,IF(F8<=150,$B$6+$B$6*$B$12,IF(F8<=160,$B$6-$B$6*$B$12,IF(F8<=170,$B$6+$B$6*$B$12,IF(F8<=180,$B$6-$B$6*$B$12,IF(F8<=190,$B$6+$B$6*$B$12,IF(F8<=200,$B$6-$B$6*$B$12,$B$6)))))))))))))))))))) -> 1000 | K8: =MIN($B$11,J8/H8) -> 2.6646281 | L8: =$B$8*(J8/(H8*K8)) -> 50 | M8: =K8*L8 -> 133.23141 | N8: =M8/$B$10 -> 1.3323141
A9: Waiting time | B9: =Model_1!B9 -> 0.083333333 | C9: hour | E9: 7 | F9: =E9*$B$2 -> 7 | G9: =MAX(0,IF(N9>=1,J9*$B$4*$B$2*(N9-1),0)) -> 8.935118 | H9: =H8+(G8-I8) -> 385.25631 | I9: =H9*$B$5*$B$2*MAX(0,1-N9) -> 0 | J9: =IF(F9<=10,$B$6,IF(F9<=20,$B$6-$B$6*$B$12,IF(F9<=30,$B$6+$B$6*$B$12,IF(F9<=40,$B$6-$B$6*$B$12,IF(F9<=50,$B$6+$B$6*$B$12,IF(F9<=60,$B$6-$B$6*$B$12,IF(F9<=70,$B$6+$B$6*$B$12,IF(F9<=80,$B$6-$B$6*$B$12,IF(F9<=90,$B$6+$B$6*$B$12,IF(F9<=100,$B$6-$B$6*$B$12,IF(F9<=110,$B$6+$B$6*$B$12,IF(F9<=120,$B$6-$B$6*$B$12,IF(F9<=130,$B$6+$B$6*$B$12,IF(F9<=140,$B$6-$B$6*$B$12,IF(F9<=150,$B$6+$B$6*$B$12,IF(F9<=160,$B$6-$B$6*$B$12,IF(F9<=170,$B$6+$B$6*$B$12,IF(F9<=180,$B$6-$B$6*$B$12,IF(F9<=190,$B$6+$B$6*$B$12,IF(F9<=200,$B$6-$B$6*$B$12,$B$6)))))))))))))))))))) -> 1000 | K9: =MIN($B$11,J9/H9) -> 2.5956745 | L9: =$B$8*(J9/(H9*K9)) -> 50 | M9: =K9*L9 -> 129.78373 | N9: =M9/$B$10 -> 1.2978373
A10: Target incom (2 rides for 50$ each) | B10: =Model_1!B10 -> 100 | C10: $/hour | E10: 8 | F10: =E10*$B$2 -> 8 | G10: =MAX(0,IF(N10>=1,J10*$B$4*$B$2*(N10-1),0)) -> 8.0525776 | H10: =H9+(G9-I9) -> 394.19143 | I10: =H10*$B$5*$B$2*MAX(0,1-N10) -> 0 | J10: =IF(F10<=10,$B$6,IF(F10<=20,$B$6-$B$6*$B$12,IF(F10<=30,$B$6+$B$6*$B$12,IF(F10<=40,$B$6-$B$6*$B$12,IF(F10<=50,$B$6+$B$6*$B$12,IF(F10<=60,$B$6-$B$6*$B$12,IF(F10<=70,$B$6+$B$6*$B$12,IF(F10<=80,$B$6-$B$6*$B$12,IF(F10<=90,$B$6+$B$6*$B$12,IF(F10<=100,$B$6-$B$6*$B$12,IF(F10<=110,$B$6+$B$6*$B$12,IF(F10<=120,$B$6-$B$6*$B$12,IF(F10<=130,$B$6+$B$6*$B$12,IF(F10<=140,$B$6-$B$6*$B$12,IF(F10<=150,$B$6+$B$6*$B$12,IF(F10<=160,$B$6-$B$6*$B$12,IF(F10<=170,$B$6+$B$6*$B$12,IF(F10<=180,$B$6-$B$6*$B$12,IF(F10<=190,$B$6+$B$6*$B$12,IF(F10<=200,$B$6-$B$6*$B$12,$B$6)))))))))))))))))))) -> 1000 | K10: =MIN($B$11,J10/H10) -> 2.5368385 | L10: =$B$8*(J10/(H10*K10)) -> 50 | M10: =K10*L10 -> 126.84193 | N10: =M10/$B$10 -> 1.2684193
A11: Max rides per hour | B11: =Model_1!B11 -> 3 | C11: ride/ hour | E11: 9 | F11: =E11*$B$2 -> 9 | G11: =MAX(0,IF(N11>=1,J11*$B$4*$B$2*(N11-1),0)) -> 7.2907978 | H11: =H10+(G10-I10) -> 402.24401 | I11: =H11*$B$5*$B$2*MAX(0,1-N11) -> 0 | J11: =IF(F11<=10,$B$6,IF(F11<=20,$B$6-$B$6*$B$12,IF(F11<=30,$B$6+$B$6*$B$12,IF(F11<=40,$B$6-$B$6*$B$12,IF(F11<=50,$B$6+$B$6*$B$12,IF(F11<=60,$B$6-$B$6*$B$12,IF(F11<=70,$B$6+$B$6*$B$12,IF(F11<=80,$B$6-$B$6*$B$12,IF(F11<=90,$B$6+$B$6*$B$12,IF(F11<=100,$B$6-$B$6*$B$12,IF(F11<=110,$B$6+$B$6*$B$12,IF(F11<=120,$B$6-$B$6*$B$12,IF(F11<=130,$B$6+$B$6*$B$12,IF(F11<=140,$B$6-$B$6*$B$12,IF(F11<=150,$B$6+$B$6*$B$12,IF(F11<=160,$B$6-$B$6*$B$12,IF(F11<=170,$B$6+$B$6*$B$12,IF(F11<=180,$B$6-$B$6*$B$12,IF(F11<=190,$B$6+$B$6*$B$12,IF(F11<=200,$B$6-$B$6*$B$12,$B$6)))))))))))))))))))) -> 1000 | K11: =MIN($B$11,J11/H11) -> 2.4860532 | L11: =$B$8*(J11/(H11*K11)) -> 50 | M11: =K11*L11 -> 124.30266 | N11: =M11/$B$10 -> 1.2430266
A12: Demand variation | B12: =Model_3!B12 -> 0.6 | E12: 10 | F12: =E12*$B$2 -> 10 | G12: =MAX(0,IF(N12>=1,J12*$B$4*$B$2*(N12-1),0)) -> 6.6269234 | H12: =H11+(G11-I11) -> 409.53481 | I12: =H12*$B$5*$B$2*MAX(0,1-N12) -> 0 | J12: =IF(F12<=10,$B$6,IF(F12<=20,$B$6-$B$6*$B$12,IF(F12<=30,$B$6+$B$6*$B$12,IF(F12<=40,$B$6-$B$6*$B$12,IF(F12<=50,$B$6+$B$6*$B$12,IF(F12<=60,$B$6-$B$6*$B$12,IF(F12<=70,$B$6+$B$6*$B$12,IF(F12<=80,$B$6-$B$6*$B$12,IF(F12<=90,$B$6+$B$6*$B$12,IF(F12<=100,$B$6-$B$6*$B$12,IF(F12<=110,$B$6+$B$6*$B$12,IF(F12<=120,$B$6-$B$6*$B$12,IF(F12<=130,$B$6+$B$6*$B$12,IF(F12<=140,$B$6-$B$6*$B$12,IF(F12<=150,$B$6+$B$6*$B$12,IF(F12<=160,$B$6-$B$6*$B$12,IF(F12<=170,$B$6+$B$6*$B$12,IF(F12<=180,$B$6-$B$6*$B$12,IF(F12<=190,$B$6+$B$6*$B$12,IF(F12<=200,$B$6-$B$6*$B$12,$B$6)))))))))))))))))))) -> 1000 | K12: =MIN($B$11,J12/H12) -> 2.4417949 | L12: =$B$8*(J12/(H12*K12)) -> 50 | M12: =K12*L12 -> 122.08974 | N12: =M12/$B$10 -> 1.2208974
A13: Entry delay time | B13: 0 | C13: hour | E13: 11 | F13: =E13*$B$2 -> 11 | G13: =MAX(0,IF(N13>=1,J13*$B$4*$B$2*(N13-1),0)) -> 0 | H13: =H12+(G12-I12) -> 416.16173 | I13: =H13*$B$5*$B$2*MAX(0,1-N13) -> 8.6464692 | J13: =IF(F13<=10,$B$6,IF(F13<=20,$B$6-$B$6*$B$12,IF(F13<=30,$B$6+$B$6*$B$12,IF(F13<=40,$B$6-$B$6*$B$12,IF(F13<=50,$B$6+$B$6*$B$12,IF(F13<=60,$B$6-$B$6*$B$12,IF(F13<=70,$B$6+$B$6*$B$12,IF(F13<=80,$B$6-$B$6*$B$12,IF(F13<=90,$B$6+$B$6*$B$12,IF(F13<=100,$B$6-$B$6*$B$12,IF(F13<=110,$B$6+$B$6*$B$12,IF(F13<=120,$B$6-$B$6*$B$12,IF(F13<=130,$B$6+$B$6*$B$12,IF(F13<=140,$B$6-$B$6*$B$12,IF(F13<=150,$B$6+$B$6*$B$12,IF(F13<=160,$B$6-$B$6*$B$12,IF(F13<=170,$B$6+$B$6*$B$12,IF(F13<=180,$B$6-$B$6*$B$12,IF(F13<=190,$B$6+$B$6*$B$12,IF(F13<=200,$B$6-$B$6*$B$12,$B$6)))))))))))))))))))) -> 400 | K13: =MIN($B$11,J13/H13) -> 0.96116479 | L13: =$B$8*(J13/(H13*K13)) -> 50 | M13: =K13*L13 -> 48.058239 | N13: =M13/$B$10 -> 0.48058239
E14: 12 | F14: =E14*$B$2 -> 12 | G14: =MAX(0,IF(N14>=1,J14*$B$4*$B$2*(N14-1),0)) -> 0 | H14: =H13+(G13-I13) -> 407.51526 | I14: =H14*$B$5*$B$2*MAX(0,1-N14) -> 8.3006104 | J14: =IF(F14<=10,$B$6,IF(F14<=20,$B$6-$B$6*$B$12,IF(F14<=30,$B$6+$B$6*$B$12,IF(F14<=40,$B$6-$B$6*$B$12,IF(F14<=50,$B$6+$B$6*$B$12,IF(F14<=60,$B$6-$B$6*$B$12,IF(F14<=70,$B$6+$B$6*$B$12,IF(F14<=80,$B$6-$B$6*$B$12,IF(F14<=90,$B$6+$B$6*$B$12,IF(F14<=100,$B$6-$B$6*$B$12,IF(F14<=110,$B$6+$B$6*$B$12,IF(F14<=120,$B$6-$B$6*$B$12,IF(F14<=130,$B$6+$B$6*$B$12,IF(F14<=140,$B$6-$B$6*$B$12,IF(F14<=150,$B$6+$B$6*$B$12,IF(F14<=160,$B$6-$B$6*$B$12,IF(F14<=170,$B$6+$B$6*$B$12,IF(F14<=180,$B$6-$B$6*$B$12,IF(F14<=190,$B$6+$B$6*$B$12,IF(F14<=200,$B$6-$B$6*$B$12,$B$6)))))))))))))))))))) -> 400 | K14: =MIN($B$11,J14/H14) -> 0.98155833 | L14: =$B$8*(J14/(H14*K14)) -> 50 | M14: =K14*L14 -> 49.077917 | N14: =M14/$B$10 -> 0.49077917
E15: 13 | F15: =E15*$B$2 -> 13 | G15: =MAX(0,IF(N15>=1,J15*$B$4*$B$2*(N15-1),0)) -> 0 | H15: =H14+(G14-I14) -> 399.21465 | I15: =H15*$B$5*$B$2*MAX(0,1-N15) -> 7.968586 | J15: =IF(F15<=10,$B$6,IF(F15<=20,$B$6-$B$6*$B$12,IF(F15<=30,$B$6+$B$6*$B$12,IF(F15<=40,$B$6-$B$6*$B$12,IF(F15<=50,$B$6+$B$6*$B$12,IF(F15<=60,$B$6-$B$6*$B$12,IF(F15<=70,$B$6+$B$6*$B$12,IF(F15<=80,$B$6-$B$6*$B$12,IF(F15<=90,$B$6+$B$6*$B$12,IF(F15<=100,$B$6-$B$6*$B$12,IF(F15<=110,$B$6+$B$6*$B$12,IF(F15<=120,$B$6-$B$6*$B$12,IF(F15<=130,$B$6+$B$6*$B$12,IF(F15<=140,$B$6-$B$6*$B$12,IF(F15<=150,$B$6+$B$6*$B$12,IF(F15<=160,$B$6-$B$6*$B$12,IF(F15<=170,$B$6+$B$6*$B$12,IF(F15<=180,$B$6-$B$6*$B$12,IF(F15<=190,$B$6+$B$6*$B$12,IF(F15<=200,$B$6-$B$6*$B$12,$B$6)))))))))))))))))))) -> 400 | K15: =MIN($B$11,J15/H15) -> 1.0019672 | L15: =$B$8*(J15/(H15*K15)) -> 50 | M15: =K15*L15 -> 50.098362 | N15: =M15/$B$10 -> 0.50098362
E16: 14 | F16: =E16*$B$2 -> 14 | G16: =MAX(0,IF(N16>=1,J16*$B$4*$B$2*(N16-1),0)) -> 0 | H16: =H15+(G15-I15) -> 391.24606 | I16: =H16*$B$5*$B$2*MAX(0,1-N16) -> 7.6498426 | J16: =IF(F16<=10,$B$6,IF(F16<=20,$B$6-$B$6*$B$12,IF(F16<=30,$B$6+$B$6*$B$12,IF(F16<=40,$B$6-$B$6*$B$12,IF(F16<=50,$B$6+$B$6*$B$12,IF(F16<=60,$B$6-$B$6*$B$12,IF(F16<=70,$B$6+$B$6*$B$12,IF(F16<=80,$B$6-$B$6*$B$12,IF(F16<=90,$B$6+$B$6*$B$12,IF(F16<=100,$B$6-$B$6*$B$12,IF(F16<=110,$B$6+$B$6*$B$12,IF(F16<=120,$B$6-$B$6*$B$12,IF(F16<=130,$B$6+$B$6*$B$12,IF(F16<=140,$B$6-$B$6*$B$12,IF(F16<=150,$B$6+$B$6*$B$12,IF(F16<=160,$B$6-$B$6*$B$12,IF(F16<=170,$B$6+$B$6*$B$12,IF(F16<=180,$B$6-$B$6*$B$12,IF(F16<=190,$B$6+$B$6*$B$12,IF(F16<=200,$B$6-$B$6*$B$12,$B$6)))))))))))))))))))) -> 400 | K16: =MIN($B$11,J16/H16) -> 1.0223745 | L16: =$B$8*(J16/(H16*K16)) -> 50 | M16: =K16*L16 -> 51.118725 | N16: =M16/$B$10 -> 0.51118725
E17: 15 | F17: =E17*$B$2 -> 15 | G17: =MAX(0,IF(N17>=1,J17*$B$4*$B$2*(N17-1),0)) -> 0 | H17: =H16+(G16-I16) -> 383.59622 | I17: =H17*$B$5*$B$2*MAX(0,1-N17) -> 7.3438489 | J17: =IF(F17<=10,$B$6,IF(F17<=20,$B$6-$B$6*$B$12,IF(F17<=30,$B$6+$B$6*$B$12,IF(F17<=40,$B$6-$B$6*$B$12,IF(F17<=50,$B$6+$B$6*$B$12,IF(F17<=60,$B$6-$B$6*$B$12,IF(F17<=70,$B$6+$B$6*$B$12,IF(F17<=80,$B$6-$B$6*$B$12,IF(F17<=90,$B$6+$B$6*$B$12,IF(F17<=100,$B$6-$B$6*$B$12,IF(F17<=110,$B$6+$B$6*$B$12,IF(F17<=120,$B$6-$B$6*$B$12,IF(F17<=130,$B$6+$B$6*$B$12,IF(F17<=140,$B$6-$B$6*$B$12,IF(F17<=150,$B$6+$B$6*$B$12,IF(F17<=160,$B$6-$B$6*$B$12,IF(F17<=170,$B$6+$B$6*$B$12,IF(F17<=180,$B$6-$B$6*$B$12,IF(F17<=190,$B$6+$B$6*$B$12,IF(F17<=200,$B$6-$B$6*$B$12,$B$6)))))))))))))))))))) -> 400 | K17: =MIN($B$11,J17/H17) -> 1.0427631 | L17: =$B$8*(J17/(H17*K17)) -> 50 | M17: =K17*L17 -> 52.138157 | N17: =M17/$B$10 -> 0.52138157
E18: 16 | F18: =E18*$B$2 -> 16 | G18: =MAX(0,IF(N18>=1,J18*$B$4*$B$2*(N18-1),0)) -> 0 | H18: =H17+(G17-I17) -> 376.25237 | I18: =H18*$B$5*$B$2*MAX(0,1-N18) -> 7.0500949 | J18: =IF(F18<=10,$B$6,IF(F18<=20,$B$6-$B$6*$B$12,IF(F18<=30,$B$6+$B$6*$B$12,IF(F18<=40,$B$6-$B$6*$B$12,IF(F18<=50,$B$6+$B$6*$B$12,IF(F18<=60,$B$6-$B$6*$B$12,IF(F18<=70,$B$6+$B$6*$B$12,IF(F18<=80,$B$6-$B$6*$B$12,IF(F18<=90,$B$6+$B$6*$B$12,IF(F18<=100,$B$6-$B$6*$B$12,IF(F18<=110,$B$6+$B$6*$B$12,IF(F18<=120,$B$6-$B$6*$B$12,IF(F18<=130,$B$6+$B$6*$B$12,IF(F18<=140,$B$6-$B$6*$B$12,IF(F18<=150,$B$6+$B$6*$B$12,IF(F18<=160,$B$6-$B$6*$B$12,IF(F18<=170,$B$6+$B$6*$B$12,IF(F18<=180,$B$6-$B$6*$B$12,IF(F18<=190,$B$6+$B$6*$B$12,IF(F18<=200,$B$6-$B$6*$B$12,$B$6)))))))))))))))))))) -> 400 | K18: =MIN($B$11,J18/H18) -> 1.0631162 | L18: =$B$8*(J18/(H18*K18)) -> 50 | M18: =K18*L18 -> 53.155811 | N18: =M18/$B$10 -> 0.53155811
E19: 17 | F19: =E19*$B$2 -> 17 | G19: =MAX(0,IF(N19>=1,J19*$B$4*$B$2*(N19-1),0)) -> 0 | H19: =H18+(G18-I18) -> 369.20228 | I19: =H19*$B$5*$B$2*MAX(0,1-N19) -> 6.7680911 | J19: =IF(F19<=10,$B$6,IF(F19<=20,$B$6-$B$6*$B$12,IF(F19<=30,$B$6+$B$6*$B$12,IF(F19<=40,$B$6-$B$6*$B$12,IF(F19<=50,$B$6+$B$6*$B$12,IF(F19<=60,$B$6-$B$6*$B$12,IF(F19<=70,$B$6+$B$6*$B$12,IF(F19<=80,$B$6-$B$6*$B$12,IF(F19<=90,$B$6+$B$6*$B$12,IF(F19<=100,$B$6-$B$6*$B$12,IF(F19<=110,$B$6+$B$6*$B$12,IF(F19<=120,$B$6-$B$6*$B$12,IF(F19<=130,$B$6+$B$6*$B$12,IF(F19<=140,$B$6-$B$6*$B$12,IF(F19<=150,$B$6+$B$6*$B$12,IF(F19<=160,$B$6-$B$6*$B$12,IF(F19<=170,$B$6+$B$6*$B$12,IF(F19<=180,$B$6-$B$6*$B$12,IF(F19<=190,$B$6+$B$6*$B$12,IF(F19<=200,$B$6-$B$6*$B$12,$B$6)))))))))))))))))))) -> 400 | K19: =MIN($B$11,J19/H19) -> 1.0834169 | L19: =$B$8*(J19/(H19*K19)) -> 50 | M19: =K19*L19 -> 54.170847 | N19: =M19/$B$10 -> 0.54170847
E20: 18 | F20: =E20*$B$2 -> 18 | G20: =MAX(0,IF(N20>=1,J20*$B$4*$B$2*(N20-1),0)) -> 0 | H20: =H19+(G19-I19) -> 362.43419 | I20: =H20*$B$5*$B$2*MAX(0,1-N20) -> 6.4973675 | J20: =IF(F20<=10,$B$6,IF(F20<=20,$B$6-$B$6*$B$12,IF(F20<=30,$B$6+$B$6*$B$12,IF(F20<=40,$B$6-$B$6*$B$12,IF(F20<=50,$B$6+$B$6*$B$12,IF(F20<=60,$B$6-$B$6*$B$12,IF(F20<=70,$B$6+$B$6*$B$12,IF(F20<=80,$B$6-$B$6*$B$12,IF(F20<=90,$B$6+$B$6*$B$12,IF(F20<=100,$B$6-$B$6*$B$12,IF(F20<=110,$B$6+$B$6*$B$12,IF(F20<=120,$B$6-$B$6*$B$12,IF(F20<=130,$B$6+$B$6*$B$12,IF(F20<=140,$B$6-$B$6*$B$12,IF(F20<=150,$B$6+$B$6*$B$12,IF(F20<=160,$B$6-$B$6*$B$12,IF(F20<=170,$B$6+$B$6*$B$12,IF(F20<=180,$B$6-$B$6*$B$12,IF(F20<=190,$B$6+$B$6*$B$12,IF(F20<=200,$B$6-$B$6*$B$12,$B$6)))))))))))))))))))) -> 400 | K20: =MIN($B$11,J20/H20) -> 1.1036486 | L20: =$B$8*(J20/(H20*K20)) -> 50 | M20: =K20*L20 -> 55.182432 | N20: =M20/$B$10 -> 0.55182432
E21: 19 | F21: =E21*$B$2 -> 19 | G21: =MAX(0,IF(N21>=1,J21*$B$4*$B$2*(N21-1),0)) -> 0 | H21: =H20+(G20-I20) -> 355.93682 | I21: =H21*$B$5*$B$2*MAX(0,1-N21) -> 6.2374728 | J21: =IF(F21<=10,$B$6,IF(F21<=20,$B$6-$B$6*$B$12,IF(F21<=30,$B$6+$B$6*$B$12,IF(F21<=40,$B$6-$B$6*$B$12,IF(F21<=50,$B$6+$B$6*$B$12,IF(F21<=60,$B$6-$B$6*$B$12,IF(F21<=70,$B$6+$B$6*$B$12,IF(F21<=80,$B$6-$B$6*$B$12,IF(F21<=90,$B$6+$B$6*$B$12,IF(F21<=100,$B$6-$B$6*$B$12,IF(F21<=110,$B$6+$B$6*$B$12,IF(F21<=120,$B$6-$B$6*$B$12,IF(F21<=130,$B$6+$B$6*$B$12,IF(F21<=140,$B$6-$B$6*$B$12,IF(F21<=150,$B$6+$B$6*$B$12,IF(F21<=160,$B$6-$B$6*$B$12,IF(F21<=170,$B$6+$B$6*$B$12,IF(F21<=180,$B$6-$B$6*$B$12,IF(F21<=190,$B$6+$B$6*$B$12,IF(F21<=200,$B$6-$B$6*$B$12,$B$6)))))))))))))))))))) -> 400 | K21: =MIN($B$11,J21/H21) -> 1.123795 | L21: =$B$8*(J21/(H21*K21)) -> 50 | M21: =K21*L21 -> 56.189748 | N21: =M21/$B$10 -> 0.56189748
E22: 20 | F22: =E22*$B$2 -> 20 | G22: =MAX(0,IF(N22>=1,J22*$B$4*$B$2*(N22-1),0)) -> 0 | H22: =H21+(G21-I21) -> 349.69935 | I22: =H22*$B$5*$B$2*MAX(0,1-N22) -> 5.9879739 | J22: =IF(F22<=10,$B$6,IF(F22<=20,$B$6-$B$6*$B$12,IF(F22<=30,$B$6+$B$6*$B$12,IF(F22<=40,$B$6-$B$6*$B$12,IF(F22<=50,$B$6+$B$6*$B$12,IF(F22<=60,$B$6-$B$6*$B$12,IF(F22<=70,$B$6+$B$6*$B$12,IF(F22<=80,$B$6-$B$6*$B$12,IF(F22<=90,$B$6+$B$6*$B$12,IF(F22<=100,$B$6-$B$6*$B$12,IF(F22<=110,$B$6+$B$6*$B$12,IF(F22<=120,$B$6-$B$6*$B$12,IF(F22<=130,$B$6+$B$6*$B$12,IF(F22<=140,$B$6-$B$6*$B$12,IF(F22<=150,$B$6+$B$6*$B$12,IF(F22<=160,$B$6-$B$6*$B$12,IF(F22<=170,$B$6+$B$6*$B$12,IF(F22<=180,$B$6-$B$6*$B$12,IF(F22<=190,$B$6+$B$6*$B$12,IF(F22<=200,$B$6-$B$6*$B$12,$B$6)))))))))))))))))))) -> 400 | K22: =MIN($B$11,J22/H22) -> 1.1438397 | L22: =$B$8*(J22/(H22*K22)) -> 50 | M22: =K22*L22 -> 57.191986 | N22: =M22/$B$10 -> 0.57191986
E23: 21 | F23: =E23*$B$2 -> 21 | G23: =MAX(0,IF(N23>=1,J23*$B$4*$B$2*(N23-1),0)) -> 63.721645 | H23: =H22+(G22-I22) -> 343.71137 | I23: =H23*$B$5*$B$2*MAX(0,1-N23) -> 0 | J23: =IF(F23<=10,$B$6,IF(F23<=20,$B$6-$B$6*$B$12,IF(F23<=30,$B$6+$B$6*$B$12,IF(F23<=40,$B$6-$B$6*$B$12,IF(F23<=50,$B$6+$B$6*$B$12,IF(F23<=60,$B$6-$B$6*$B$12,IF(F23<=70,$B$6+$B$6*$B$12,IF(F23<=80,$B$6-$B$6*$B$12,IF(F23<=90,$B$6+$B$6*$B$12,IF(F23<=100,$B$6-$B$6*$B$12,IF(F23<=110,$B$6+$B$6*$B$12,IF(F23<=120,$B$6-$B$6*$B$12,IF(F23<=130,$B$6+$B$6*$B$12,IF(F23<=140,$B$6-$B$6*$B$12,IF(F23<=150,$B$6+$B$6*$B$12,IF(F23<=160,$B$6-$B$6*$B$12,IF(F23<=170,$B$6+$B$6*$B$12,IF(F23<=180,$B$6-$B$6*$B$12,IF(F23<=190,$B$6+$B$6*$B$12,IF(F23<=200,$B$6-$B$6*$B$12,$B$6)))))))))))))))))))) -> 1600 | K23: =MIN($B$11,J23/H23) -> 3 | L23: =$B$8*(J23/(H23*K23)) -> 77.584476 | M23: =K23*L23 -> 232.75343 | N23: =M23/$B$10 -> 2.3275343
E24: 22 | F24: =E24*$B$2 -> 22 | G24: =MAX(0,IF(N24>=1,J24*$B$4*$B$2*(N24-1),0)) -> 46.248621 | H24: =H23+(G23-I23) -> 407.43302 | I24: =H24*$B$5*$B$2*MAX(0,1-N24) -> 0 | J24: =IF(F24<=10,$B$6,IF(F24<=20,$B$6-$B$6*$B$12,IF(F24<=30,$B$6+$B$6*$B$12,IF(F24<=40,$B$6-$B$6*$B$12,IF(F24<=50,$B$6+$B$6*$B$12,IF(F24<=60,$B$6-$B$6*$B$12,IF(F24<=70,$B$6+$B$6*$B$12,IF(F24<=80,$B$6-$B$6*$B$12,IF(F24<=90,$B$6+$B$6*$B$12,IF(F24<=100,$B$6-$B$6*$B$12,IF(F24<=110,$B$6+$B$6*$B$12,IF(F24<=120,$B$6-$B$6*$B$12,IF(F24<=130,$B$6+$B$6*$B$12,IF(F24<=140,$B$6-$B$6*$B$12,IF(F24<=150,$B$6+$B$6*$B$12,IF(F24<=160,$B$6-$B$6*$B$12,IF(F24<=170,$B$6+$B$6*$B$12,IF(F24<=180,$B$6-$B$6*$B$12,IF(F24<=190,$B$6+$B$6*$B$12,IF(F24<=200,$B$6-$B$6*$B$12,$B$6)))))))))))))))))))) -> 1600 | K24: =MIN($B$11,J24/H24) -> 3 | L24: =$B$8*(J24/(H24*K24)) -> 65.450431 | M24: =K24*L24 -> 196.35129 | N24: =M24/$B$10 -> 1.9635129
E25: 23 | F25: =E25*$B$2 -> 23 | G25: =MAX(0,IF(N25>=1,J25*$B$4*$B$2*(N25-1),0)) -> 36.640851 | H25: =H24+(G24-I24) -> 453.68164 | I25: =H25*$B$5*$B$2*MAX(0,1-N25) -> 0 | J25: =IF(F25<=10,$B$6,IF(F25<=20,$B$6-$B$6*$B$12,IF(F25<=30,$B$6+$B$6*$B$12,IF(F25<=40,$B$6-$B$6*$B$12,IF(F25<=50,$B$6+$B$6*$B$12,IF(F25<=60,$B$6-$B$6*$B$12,IF(F25<=70,$B$6+$B$6*$B$12,IF(F25<=80,$B$6-$B$6*$B$12,IF(F25<=90,$B$6+$B$6*$B$12,IF(F25<=100,$B$6-$B$6*$B$12,IF(F25<=110,$B$6+$B$6*$B$12,IF(F25<=120,$B$6-$B$6*$B$12,IF(F25<=130,$B$6+$B$6*$B$12,IF(F25<=140,$B$6-$B$6*$B$12,IF(F25<=150,$B$6+$B$6*$B$12,IF(F25<=160,$B$6-$B$6*$B$12,IF(F25<=170,$B$6+$B$6*$B$12,IF(F25<=180,$B$6-$B$6*$B$12,IF(F25<=190,$B$6+$B$6*$B$12,IF(F25<=200,$B$6-$B$6*$B$12,$B$6)))))))))))))))))))) -> 1600 | K25: =MIN($B$11,J25/H25) -> 3 | L25: =$B$8*(J25/(H25*K25)) -> 58.778369 | M25: =K25*L25 -> 176.33511 | N25: =M25/$B$10 -> 1.7633511
... E202: 200 | F202: =E202*$B$2 -> 200 | G202: =MAX(0,IF(N202>=1,J202*$B$4*$B$2*(N202-1),0)) -> 0 | H202: =H201+(G201-I201) -> 530.47898 | I202: =H202*$B$5*$B$2*MAX(0,1-N202) -> 13.219159 | J202: =IF(F202<=10,$B$6,IF(F202<=20,$B$6-$B$6*$B$12,IF(F202<=30,$B$6+$B$6*$B$12,IF(F202<=40,$B$6-$B$6*$B$12,IF(F202<=50,$B$6+$B$6*$B$12,IF(F202<=60,$B$6-$B$6*$B$12,IF(F202<=70,$B$6+$B$6*$B$12,IF(F202<=80,$B$6-$B$6*$B$12,IF(F202<=90,$B$6+$B$6*$B$12,IF(F202<=100,$B$6-$B$6*$B$12,IF(F202<=110,$B$6+$B$6*$B$12,IF(F202<=120,$B$6-$B$6*$B$12,IF(F202<=130,$B$6+$B$6*$B$12,IF(F202<=140,$B$6-$B$6*$B$12,IF(F202<=150,$B$6+$B$6*$B$12,IF(F202<=160,$B$6-$B$6*$B$12,IF(F202<=170,$B$6+$B$6*$B$12,IF(F202<=180,$B$6-$B$6*$B$12,IF(F202<=190,$B$6+$B$6*$B$12,IF(F202<=200,$B$6-$B$6*$B$12,$B$6)))))))))))))))))))) -> 400 | K202: =MIN($B$11,J202/H202) -> 0.75403553 | L202: =$B$8*(J202/(H202*K202)) -> 50 | M202: =K202*L202 -> 37.701777 | N202: =M202/$B$10 -> 0.37701777

Sheet Contrast
B1: Entry flow, car/ hour Mod 1/ Mod 2/ Mod 3/ Mod 4 | F1: Number of cars, car Mod 1/ Mod 2/ Mod 3/ Mod 4 | J1: Exit flow, car/ hour Mod 1/ Mod 2/ Mod 3/ Mod 4 | N1: Number of passengers, people Mod 1/ Mod 2/ Mod 3/ Mod 4 | R1: Rides per hour, ride/ hour Mod 1/ Mod 2/ Mod 3/ Mod 4 | V1: Price per ride, $ Mod 1/ Mod 2/ Mod 3/ Mod 4 | Z1: Hourly incom per car, $/ hour Mod 1/ Mod 2/ Mod 3/ Mod 4 | AD1: Job attractiveness Mod 1/ Mod 2/ Mod 3/ Mod 4
A2: 0 | B2: =Model_1!G2 -> 0 | C2: =Model_2!G2 -> 0 | D2: =Model_3!G2 -> 0 | E2: =Model_4!G2 -> 0 | F2: =Model_1!H2 -> 300 | G2: =Model_2!H2 -> 300 | H2: =Model_3!H2 -> 300 | I2: =Model_4!H2 -> 300 | J2: =Model_1!I2 -> 0 | K2: =Model_2!I2 -> 0 | L2: =Model_3!I2 -> 0 | M2: =Model_4!I2 -> 0 | N2: =Model_1!J2 -> 1000 | O2: =Model_2!J2 -> 1000 | P2: =Model_3!J2 -> 1000 | Q2: =Model_4!J2 -> 1000 | R2: =Model_1!K2 -> 0 | S2: =Model_2!K2 -> 0 | T2: =Model_3!K2 -> 0 | U2: =Model_4!K2 -> 0 | V2: =Model_1!L2 -> 0 | W2: =Model_2!L2 -> 0 | X2: =Model_3!L2 -> 0 | Y2: =Model_4!L2 -> 0 | Z2: =Model_1!M2 -> 0 | AA2: =Model_2!M2 -> 0 | AB2: =Model_3!M2 -> 0 | AC2: =Model_4!M2 -> 0 | AD2: =Model_1!N2 -> 0 | AE2: =Model_2!N2 -> 0 | AF2: =Model_3!N2 -> 0 | AG2: =Model_4!N2 -> 0
A3: 1 | B3: =Model_1!G3 -> 20 | C3: =Model_2!G3 -> 20 | D3: =Model_3!G3 -> 0 | E3: =Model_4!G3 -> 20 | F3: =Model_1!H3 -> 300 | G3: =Model_2!H3 -> 300 | H3: =Model_3!H3 -> 300 | I3: =Model_4!H3 -> 300 | J3: =Model_1!I3 -> 0 | K3: =Model_2!I3 -> 0 | L3: =Model_3!I3 -> 0 | M3: =Model_4!I3 -> 0 | N3: =Model_1!J3 -> 1000 | O3: =Model_2!J3 -> 1000 | P3: =Model_3!J3 -> 1000 | Q3: =Model_4!J3 -> 1000 | R3: =Model_1!K3 -> 3 | S3: =Model_2!K3 -> 3 | T3: =Model_3!K3 -> 3 | U3: =Model_4!K3 -> 3 | V3: =Model_1!L3 -> 55.555556 | W3: =Model_2!L3 -> 55.555556 | X3: =Model_3!L3 -> 55.555556 | Y3: =Model_4!L3 -> 55.555556 | Z3: =Model_1!M3 -> 166.66667 | AA3: =Model_2!M3 -> 166.66667 | AB3: =Model_3!M3 -> 166.66667 | AC3: =Model_4!M3 -> 166.66667 | AD3: =Model_1!N3 -> 1.6666667 | AE3: =Model_2!N3 -> 1.6666667 | AF3: =Model_3!N3 -> 1.6666667 | AG3: =Model_4!N3 -> 1.6666667
A4: 2 | B4: =Model_1!G4 -> 16.875 | C4: =Model_2!G4 -> 16.875 | D4: =Model_3!G4 -> 0 | E4: =Model_4!G4 -> 16.875 | F4: =Model_1!H4 -> 320 | G4: =Model_2!H4 -> 320 | H4: =Model_3!H4 -> 300 | I4: =Model_4!H4 -> 320 | J4: =Model_1!I4 -> 0 | K4: =Model_2!I4 -> 0 | L4: =Model_3!I4 -> 0 | M4: =Model_4!I4 -> 0 | N4: =Model_1!J4 -> 1000 | O4: =Model_2!J4 -> 1000 | P4: =Model_3!J4 -> 1000 | Q4: =Model_4!J4 -> 1000 | R4: =Model_1!K4 -> 3 | S4: =Model_2!K4 -> 3 | T4: =Model_3!K4 -> 3 | U4: =Model_4!K4 -> 3 | V4: =Model_1!L4 -> 52.083333 | W4: =Model_2!L4 -> 52.083333 | X4: =Model_3!L4 -> 55.555556 | Y4: =Model_4!L4 -> 52.083333 | Z4: =Model_1!M4 -> 156.25 | AA4: =Model_2!M4 -> 156.25 | AB4: =Model_3!M4 -> 166.66667 | AC4: =Model_4!M4 -> 156.25 | AD4: =Model_1!N4 -> 1.5625 | AE4: =Model_2!N4 -> 1.5625 | AF4: =Model_3!N4 -> 1.6666667 | AG4: =Model_4!N4 -> 1.5625
A5: 3 | B5: =Model_1!G5 -> 14.526902 | C5: =Model_2!G5 -> 65.988868 | D5: =Model_3!G5 -> 0 | E5: =Model_4!G5 -> 14.526902 | F5: =Model_1!H5 -> 336.875 | G5: =Model_2!H5 -> 336.875 | H5: =Model_3!H5 -> 300 | I5: =Model_4!H5 -> 336.875 | J5: =Model_1!I5 -> 0 | K5: =Model_2!I5 -> 0 | L5: =Model_3!I5 -> 0 | M5: =Model_4!I5 -> 0 | N5: =Model_1!J5 -> 1000 | O5: =Model_2!J5 -> 1600 | P5: =Model_3!J5 -> 1600 | Q5: =Model_4!J5 -> 1000 | R5: =Model_1!K5 -> 2.9684601 | S5: =Model_2!K5 -> 3 | T5: =Model_3!K5 -> 3 | U5: =Model_4!K5 -> 2.9684601 | V5: =Model_1!L5 -> 50 | W5: =Model_2!L5 -> 79.158936 | X5: =Model_3!L5 -> 88.888889 | Y5: =Model_4!L5 -> 50 | Z5: =Model_1!M5 -> 148.42301 | AA5: =Model_2!M5 -> 237.47681 | AB5: =Model_3!M5 -> 266.66667 | AC5: =Model_4!M5 -> 148.42301 | AD5: =Model_1!N5 -> 1.4842301 | AE5: =Model_2!N5 -> 2.3747681 | AF5: =Model_3!N5 -> 2.6666667 | AG5: =Model_4!N5 -> 1.4842301
A6: 4 | B6: =Model_1!G6 -> 12.686166 | C6: =Model_2!G6 -> 7.233421 | D6: =Model_3!G6 -> 0 | E6: =Model_4!G6 -> 12.686166 | F6: =Model_1!H6 -> 351.4019 | G6: =Model_2!H6 -> 402.86387 | H6: =Model_3!H6 -> 300 | I6: =Model_4!H6 -> 351.4019 | J6: =Model_1!I6 -> 0 | K6: =Model_2!I6 -> 0 | L6: =Model_3!I6 -> 0 | M6: =Model_4!I6 -> 0 | N6: =Model_1!J6 -> 1000 | O6: =Model_2!J6 -> 1000 | P6: =Model_3!J6 -> 1000 | Q6: =Model_4!J6 -> 1000 | R6: =Model_1!K6 -> 2.8457444 | S6: =Model_2!K6 -> 2.4822281 | T6: =Model_3!K6 -> 3 | U6: =Model_4!K6 -> 2.8457444 | V6: =Model_1!L6 -> 50 | W6: =Model_2!L6 -> 50 | X6: =Model_3!L6 -> 55.555556 | Y6: =Model_4!L6 -> 50 | Z6: =Model_1!M6 -> 142.28722 | AA6: =Model_2!M6 -> 124.1114 | AB6: =Model_3!M6 -> 166.66667 | AC6: =Model_4!M6 -> 142.28722 | AD6: =Model_1!N6 -> 1.4228722 | AE6: =Model_2!N6 -> 1.241114 | AF6: =Model_3!N6 -> 1.6666667 | AG6: =Model_4!N6 -> 1.4228722
A7: 5 | B7: =Model_1!G7 -> 11.198823 | C7: =Model_2!G7 -> 6.5766865 | D7: =Model_3!G7 -> 0 | E7: =Model_4!G7 -> 11.198823 | F7: =Model_1!H7 -> 364.08807 | G7: =Model_2!H7 -> 410.09729 | H7: =Model_3!H7 -> 300 | I7: =Model_4!H7 -> 364.08807 | J7: =Model_1!I7 -> 0 | K7: =Model_2!I7 -> 0 | L7: =Model_3!I7 -> 0 | M7: =Model_4!I7 -> 0 | N7: =Model_1!J7 -> 1000 | O7: =Model_2!J7 -> 1000 | P7: =Model_3!J7 -> 1000 | Q7: =Model_4!J7 -> 1000 | R7: =Model_1!K7 -> 2.7465882 | S7: =Model_2!K7 -> 2.4384458 | T7: =Model_3!K7 -> 3 | U7: =Model_4!K7 -> 2.7465882 | V7: =Model_1!L7 -> 50 | W7: =Model_2!L7 -> 50 | X7: =Model_3!L7 -> 55.555556 | Y7: =Model_4!L7 -> 50 | Z7: =Model_1!M7 -> 137.32941 | AA7: =Model_2!M7 -> 121.92229 | AB7: =Model_3!M7 -> 166.66667 | AC7: =Model_4!M7 -> 137.32941 | AD7: =Model_1!N7 -> 1.3732941 | AE7: =Model_2!N7 -> 1.2192229 | AF7: =Model_3!N7 -> 1.6666667 | AG7: =Model_4!N7 -> 1.3732941
A8: 6 | B8: =Model_1!G8 -> 9.9694217 | C8: =Model_2!G8 -> 44.158383 | D8: =Model_3!G8 -> 32 | E8: =Model_4!G8 -> 9.9694217 | F8: =Model_1!H8 -> 375.28689 | G8: =Model_2!H8 -> 416.67398 | H8: =Model_3!H8 -> 300 | I8: =Model_4!H8 -> 375.28689 | J8: =Model_1!I8 -> 0 | K8: =Model_2!I8 -> 0 | L8: =Model_3!I8 -> 0 | M8: =Model_4!I8 -> 0 | N8: =Model_1!J8 -> 1000 | O8: =Model_2!J8 -> 1600 | P8: =Model_3!J8 -> 1600 | Q8: =Model_4!J8 -> 1000 | R8: =Model_1!K8 -> 2.6646281 | S8: =Model_2!K8 -> 3 | T8: =Model_3!K8 -> 3 | U8: =Model_4!K8 -> 2.6646281 | V8: =Model_1!L8 -> 50 | W8: =Model_2!L8 -> 63.998877 | X8: =Model_3!L8 -> 88.888889 | Y8: =Model_4!L8 -> 50 | Z8: =Model_1!M8 -> 133.23141 | AA8: =Model_2!M8 -> 191.99663 | AB8: =Model_3!M8 -> 266.66667 | AC8: =Model_4!M8 -> 133.23141 | AD8: =Model_1!N8 -> 1.3323141 | AE8: =Model_2!N8 -> 1.9199663 | AF8: =Model_3!N8 -> 2.6666667 | AG8: =Model_4!N8 -> 1.3323141
